Workbook

Sheet Overview
A1: East, Central & Southern Africa — Company Expansion & Infrastructure Tracker
A3: Source: original web research (news, press releases, government/investment-authority sites), compiled September 2026 — this fills the FACT_COMPANY and FACT_INFRASTRUCTURE tables from your data model, which no ready-made government dataset covers the way UIS/WITS covers macro and trade indicators.
A4: Scope: all 19 countries in your data model's regional expansion — Kenya, Tanzania, Uganda, Rwanda, Ethiopia, Burundi, Comoros, Djibouti, DRC Congo, Eritrea, Madagascar, Malawi, Mauritius, Mozambique, Seychelles, Somalia, South Sudan, Zambia and Zimbabwe. Company entries are real, named companies with a documented, sourced expansion signal roughly 2019-2026 (older infrastructure projects are included where the signal is the most recent verifiable status update).
A6: How this workbook is organized
A7: Same structure as your other workbooks: one flat table per fact (Companies, Infrastructure), columns grouped and color-banded by theme, with a live-formula Opportunity Score on the Companies sheet. See the Methodology sheet for exactly how that score is built — it is fully transparent and recalculates if you edit the underlying data.
A11: Sheet | B11: Contents
A12: Methodology | B12: The Opportunity Score rubric — every scoring band spelled out, editable, and referenced live by formulas on the Companies sheet.
A13: Companies | B13: 109 real, sourced companies with a recent East Africa expansion signal — this is FACT_COMPANY.
A14: Infrastructure | B14: 66 real, sourced SEZs, industrial parks, ports, logistics hubs and data centres — this is FACT_INFRASTRUCTURE.
A16: Coverage by country
A17: Country | B17: Companies / Infrastructure projects found
A18: Burundi | B18: 2 companies, 1 infrastructure projects
A19: Comoros | B19: 2 companies, 2 infrastructure projects
A20: Djibouti | B20: 4 companies, 3 infrastructure projects
A21: DRC Congo | B21: 4 companies, 2 infrastructure projects
A22: Eritrea | B22: 1 companies, 1 infrastructure projects
A23: Ethiopia | B23: 12 companies, 7 infrastructure projects
A24: Kenya | B24: 14 companies, 9 infrastructure projects
A25: Madagascar | B25: 3 companies, 2 infrastructure projects
A26: Malawi | B26: 4 companies, 3 infrastructure projects
A27: Mauritius | B27: 3 companies, 2 infrastructure projects
A28: Mozambique | B28: 3 companies, 2 infrastructure projects
... A36: Zimbabwe | B36: 5 companies, 3 infrastructure projects
A38: Data notes
A39: • This data does not come from a single published dataset (unlike the UIS/WITS-based workbooks) — it was compiled entry-by-entry from live web research. Every row carries its own source title, URL and publication date; open the link before relying on a figure for a decision.
A40: • "Investment Est. (US$ Million)" on the Companies sheet is the compiler's best-effort numeric read of the "Investment (as disclosed)" text in the same row — ranges use the midpoint, EUR figures are converted at roughly 1.08 USD/EUR, and an "up to $X" or "initial $X (potential up to $Y)" figure uses the stated $X. Where nothing was publicly disclosed, both the text and the number are marked accordingly and the row still scores (see Methodology) rather than being dropped.
A41: • A company or project with no strong, sourced, recent signal in a given industry/country/type combination was left out rather than padded with a weak or stale example — so an empty combination usually means "not found", not "doesn't exist".
A42: • UAE-linked entities (DP World, Gulftainer, Majid Al Futtaim, G42) recur across several countries — this matches the DIM_COUNTRY inclusion of UAE as a major investor into East Africa rather than as a fifth target market for this table.
A43: • The Kenya Gross County Product workbook (separate file) is Kenya-only, sub-national GDP data — it does not overlap with or substitute for this company/infrastructure research.
A44: • Recency Score bands were set to a 2020-2023 window at your request. Because almost every signal in this workbook is actually dated 2023-2026, nearly all rows now score the maximum 25 points here — this sub-score currently does not differentiate rows the way Investment, Facility Type and Infrastructure Synergy do. Say the word if you'd like it rebased to the years the data actually spans.
A45: • Megabrand de-emphasis: at your request, several rows that previously led with a globally-famous parent brand now lead with the real, less-famous entity actually operating on the ground — e.g. Kenya's Coca-Cola row now profiles Amsons Group's Bamburi Cement acquisition, Oracle's row now profiles Huawei's Konza Technopolis cloud data centre, Volkswagen's Kenya row now leads with local assembler Kenya Vehicle Manufacturers (KVM), and Ethiopia's Heineken/Carrefour/Mastercard rows now lead with their actual local operating partners (Komari Beverage, Queens Supermarket, EagleLion/StarPay) rather than the multinational name. Seven of the fourteen megabrand rows you flagged were swapped or relabeled this way, backed by the same sourcing standard as the rest of the sheet; the remaining seven (Microsoft, AWS and Majid Al Futtaim in Kenya; Volkswagen and BioNTech in Rwanda; Vodacom in Tanzania; MTN in Uganda) are left as the original global entity because no equally well-sourced regional alternative could be verified this session — a research-tool budget limit was hit partway through. These are flagged for a follow-up pass rather than guessed at.

Sheet Methodology
A1: Opportunity Score Methodology
A3: Opportunity Score (0-100) is a transparent, additive index built entirely from data already on the Companies sheet, computed live by formula — it recalculates automatically if you edit the underlying rows or the point bands below. It combines four signals: how large the disclosed investment is, how recent the signal is, how durable the facility type is (a plant or data centre implies more committed presence than a single retail store), and whether the country already has a strong infrastructure ecosystem (SEZs, parks, ports, data centres) to support it. It is a starting filter for prioritizing outreach, not a definitive ranking — adjust the bands below to match your own judgment.
A8: 1. Investment Score (max 40 pts) — from Investment Est. (US$ Million)
A9: Band | B9: Points
A10: >= $100 million | B10: 40
A11: $20M to <$100M | B11: 32
A12: $5M to <$20M | B12: 24
A13: $1M to <$5M | B13: 16
A14: > $0 to <$1M | B14: 8
A15: Not disclosed | B15: 12
A17: 2. Recency Score (max 25 pts) — from Signal Year
A18: Band | B18: Points
A19: 2023 or later | B19: 25
A20: 2022 | B20: 20
A21: 2021 | B21: 14
A22: 2020 | B22: 8
A23: Before 2020 / unclear | B23: 5
A25: 3. Facility Type Score (max 20 pts) — from Facility Type
A26: Facility Type | B26: Points
A27: Manufacturing Plant | B27: 20
A28: Data Centre | B28: 20
A29: Hospital/Pharma Plant | B29: 18
A30: Construction Project | B30: 16
A31: Distribution Center | B31: 14
A32: R&D Centre | B32: 14
A33: Regional HQ / Network Infrastructure | B33: 12
A34: Regional HQ | B34: 10
A35: Retail Store/Mall | B35: 8
A36: (any other / unlisted) | B36: 12
A38: 4. Infrastructure Synergy Score (max 15 pts) — from count of Infrastructure-sheet projects in the same country
A39: Band | B39: Points
A40: 4 or more infrastructure projects in that country | B40: 15
A41: 2-3 infrastructure projects in that country | B41: 10
A42: 1 infrastructure project in that country | B42: 5
A43: 0 infrastructure projects in that country | B43: 0
A45: Opportunity Tier (from total Opportunity Score)
A46: >= 70 | B46: High
A47: 50-69 | B47: Medium
A48: < 50 | B48: Watch

Sheet Companies
A1: Company Profile | F1: Expansion Signal | K1: Opportunity Scoring | Q1: Source
A2: Country | B2: Company | C2: Industry | D2: HQ | E2: East Africa Presence | F2: Expansion Signal | G2: Signal Year | H2: Investment (as disclosed) | I2: Investment Est. (US$ Million) | J2: Facility Type | K2: Investment Score | L2: Recency Score | M2: Facility Type Score | N2: Infrastructure Synergy Score | O2: Opportunity Score | P2: Opportunity Tier | Q2: Source Title | R2: Source URL | S2: Source Date
A3: Burundi | B3: SOSUMO (Société Sucrière du Moso) | C3: Manufacturing | D3: Bujumbura, Burundi (state-owned) | E3: SOSUMO operates Burundi's only sugar factory and sugarcane plantations in the Moso region, supplying the domestic sugar market. | F3: Burundi's Council of Ministers reviewed and endorsed progress on SOSUMO's rehabilitation, modernization and extension project (roadmap approved June 9, 2021), aimed at expanding milling capacity contingent on securing sugarcane supply. | G3: 2021 | H3: 105,993,995,058 BIF (~US$53M at 2021 rates) | I3: 53 | J3: Manufacturing Plant | K3: =IF(I3="",12,IF(I3>=100,40,IF(I3>=20,32,IF(I3>=5,24,IF(I3>=1,16,8))))) -> 32 | L3: =IF(G3="",5,IF(G3>=2023,25,IF(G3>=2022,20,IF(G3>=2021,14,IF(G3>=2020,8,5))))) -> 14 | M3: =IFERROR(INDEX(Methodology!$B$27:$B$36,MATCH(J3,Methodology!$A$27:$A$36,0)),12) -> 20 | N3: =IF(COUNTIF(Infrastructure!$A:$A,A3)>=4,15,IF(COUNTIF(Infrastructure!$A:$A,A3)>=2,10,IF(COUNTIF(Infrastructure!$A:$A,A3)>=1,5,0))) -> 5 | O3: =K3+L3+M3+N3 -> 71 | P3: =IF(O3>=70,"High",IF(O3>=50,"Medium","Watch")) -> High | Q3: The SOSUMO rehabilitation, modernization and extension project is reaching a satisfactory stage | R3: https://english.abpinfo.bi/2021/06/12/the-sosumo-rehabilitation-modernization-and-extension-project-is-reaching-a-satisfactory-stage/ | S3: 2021-06-12
A4: Burundi | B4: Lumitel (Viettel Burundi S.A.) | C4: Technology | D4: Hanoi, Vietnam (Viettel Group) | E4: Lumitel is Burundi's leading mobile operator, a subsidiary of Vietnam's Viettel Group operating 2G/3G/4G mobile, fixed and mobile-money services nationwide since 2015. | F4: Lumitel and the World Bank/PAFEN signed a $10M+ public-private broadband expansion contract (Lumitel contributing $5.62M, World Bank $4.37M) to bring high-speed internet to 86 hills across 14 provinces, launched March 2, 2026; this follows an earlier announced plan to invest $20M to extend 4G coverage to 75% of the population by 2030. | G4: 2026 | H4: $10M+ (World Bank $4.37M + Lumitel $5.62M) for the 2026 broadband project; separately, $20M announced for 4G expansion through 2030 | I4: 10 | J4: Regional HQ / Network Infrastructure | K4: =IF(I4="",12,IF(I4>=100,40,IF(I4>=20,32,IF(I4>=5,24,IF(I4>=1,16,8))))) -> 24 | L4: =IF(G4="",5,IF(G4>=2023,25,IF(G4>=2022,20,IF(G4>=2021,14,IF(G4>=2020,8,5))))) -> 25 | M4: =IFERROR(INDEX(Methodology!$B$27:$B$36,MATCH(J4,Methodology!$A$27:$A$36,0)),12) -> 12 | N4: =IF(COUNTIF(Infrastructure!$A:$A,A4)>=4,15,IF(COUNTIF(Infrastructure!$A:$A,A4)>=2,10,IF(COUNTIF(Infrastructure!$A:$A,A4)>=1,5,0))) -> 5 | O4: =K4+L4+M4+N4 -> 66 | P4: =IF(O4>=70,"High",IF(O4>=50,"Medium","Watch")) -> Medium | Q4: Lumitel Burundi Launches $10M High-Speed Internet Project Across the Country | R4: https://techafricanews.com/2026/03/04/lumitel-burundi-launches-10m-high-speed-internet-project-across-the-country/ | S4: 2026-03-04
A5: Comoros | B5: AD Ports Group (via Serdal International joint venture) | C5: Logistics | D5: Abu Dhabi, United Arab Emirates | E5: AD Ports Group entered Comoros through Serdal International, a joint venture with Abu Dhabi-based Resources Investment, to operate maritime trade and passenger/vehicle ferry services between the islands. | F5: Serdal International launched a new passenger-and-vehicle ferry service (vessel 'Yameela', 190 passengers/45 vehicles) connecting Moroni (Grande Comore) and Mutsamudu (Anjouan) on September 12, 2025, in a ceremony attended by the Comorian President. | G5: 2025 | H5: Not disclosed | J5: Distribution Center | K5: =IF(I5="",12,IF(I5>=100,40,IF(I5>=20,32,IF(I5>=5,24,IF(I5>=1,16,8))))) -> 12 | L5: =IF(G5="",5,IF(G5>=2023,25,IF(G5>=2022,20,IF(G5>=2021,14,IF(G5>=2020,8,5))))) -> 25 | M5: =IFERROR(INDEX(Methodology!$B$27:$B$36,MATCH(J5,Methodology!$A$27:$A$36,0)),12) -> 14 | N5: =IF(COUNTIF(Infrastructure!$A:$A,A5)>=4,15,IF(COUNTIF(Infrastructure!$A:$A,A5)>=2,10,IF(COUNTIF(Infrastructure!$A:$A,A5)>=1,5,0))) -> 10 | O5: =K5+L5+M5+N5 -> 61 | P5: =IF(O5>=70,"High",IF(O5>=50,"Medium","Watch")) -> Medium | Q5: Serdal International Launches New Passenger and Auto Ferry Service in The Comoros | R5: https://www.adportsgroup.com/en/news-and-media/2025/09/12/serdal-international-launches-new-passenger-and-auto-ferry-service-in-the-comoros | S5: 2025-09-12
A6: Comoros | B6: Axian Telecom (Yas Comoros / Telecom Comores SA) | C6: Technology | D6: Antananarivo, Madagascar | E6: Axian Telecom, via its Comoros subsidiary Telecom Comores SA (branded Yas Comoros), is the country's second mobile network operator, providing mobile, fixed broadband and mobile-money services across the archipelago. | F6: IFC approved (Dec 17, 2024) and signed (May 30, 2025) a senior secured loan of up to €25M (~US$27M) to Telecom Comores SA to fund capital expenditure and a 2024-2026 mobile network expansion program, including 5G and fibre-to-the-home/office rollout, disbursed October 10, 2025. | G6: 2024 | H6: Up to €25 million (~US$27 million) | I6: 27 | J6: Regional HQ / Network Infrastructure | K6: =IF(I6="",12,IF(I6>=100,40,IF(I6>=20,32,IF(I6>=5,24,IF(I6>=1,16,8))))) -> 32 | L6: =IF(G6="",5,IF(G6>=2023,25,IF(G6>=2022,20,IF(G6>=2021,14,IF(G6>=2020,8,5))))) -> 25 | M6: =IFERROR(INDEX(Methodology!$B$27:$B$36,MATCH(J6,Methodology!$A$27:$A$36,0)),12) -> 12 | N6: =IF(COUNTIF(Infrastructure!$A:$A,A6)>=4,15,IF(COUNTIF(Infrastructure!$A:$A,A6)>=2,10,IF(COUNTIF(Infrastructure!$A:$A,A6)>=1,5,0))) -> 10 | O6: =K6+L6+M6+N6 -> 79 | P6: =IF(O6>=70,"High",IF(O6>=50,"Medium","Watch")) -> High | Q6: 49849 - Axian Comoros II & Tanzania | R6: https://disclosures.ifc.org/project-detail/ESRS/49849/axian-comoros-ii-tanzania | S6: 2025-10-10
A7: Djibouti | B7: Golden Africa Djibouti (HSA Group / Pacific Inter-Link) | C7: Manufacturing | D7: Sana'a, Yemen (HSA Group) | E7: Golden Africa operates an edible-oil refining and packing complex next to Doraleh port, exporting palm and sunflower oil products to Ethiopia, Somalia, Yemen and beyond. | F7: Following its ~$30M initial investment, the company announced a further $5 million investment in new machinery to raise monthly processing capacity, alongside plans for a soap manufacturing facility. | G7: 2019 | H7: $5 million (capacity-expansion phase); $30 million (original facility) | I7: 5 | J7: Manufacturing Plant | K7: =IF(I7="",12,IF(I7>=100,40,IF(I7>=20,32,IF(I7>=5,24,IF(I7>=1,16,8))))) -> 24 | L7: =IF(G7="",5,IF(G7>=2023,25,IF(G7>=2022,20,IF(G7>=2021,14,IF(G7>=2020,8,5))))) -> 5 | M7: =IFERROR(INDEX(Methodology!$B$27:$B$36,MATCH(J7,Methodology!$A$27:$A$36,0)),12) -> 20 | N7: =IF(COUNTIF(Infrastructure!$A:$A,A7)>=4,15,IF(COUNTIF(Infrastructure!$A:$A,A7)>=2,10,IF(COUNTIF(Infrastructure!$A:$A,A7)>=1,5,0))) -> 10 | O7: =K7+L7+M7+N7 -> 59 | P7: =IF(O7>=70,"High",IF(O7>=50,"Medium","Watch")) -> Medium | Q7: Palm oil: Golden Africa thinks big in East Africa | R7: https://www.theafricareport.com/22460/palm-oil-golden-africa-thinks-big-in-east-africa/ | S7: 2019
A8: Djibouti | B8: Saudi Ajyal Petroleum and Energy Company | C8: Manufacturing | D8: Saudi Arabia | E8: Saudi Ajyal is developing a large-scale oil refinery in the Djibouti Damerjog International Park (DDIP), positioned to serve regional Horn of Africa fuel demand. | F8: Cornerstone for a 300,000 barrels-per-day refinery on 300 hectares in DDIP was laid in June 2024, expected to create roughly 10,000 direct jobs. | G8: 2024 | H8: $12.7 billion | I8: 12700 | J8: Manufacturing Plant | K8: =IF(I8="",12,IF(I8>=100,40,IF(I8>=20,32,IF(I8>=5,24,IF(I8>=1,16,8))))) -> 40 | L8: =IF(G8="",5,IF(G8>=2023,25,IF(G8>=2022,20,IF(G8>=2021,14,IF(G8>=2020,8,5))))) -> 25 | M8: =IFERROR(INDEX(Methodology!$B$27:$B$36,MATCH(J8,Methodology!$A$27:$A$36,0)),12) -> 20 | N8: =IF(COUNTIF(Infrastructure!$A:$A,A8)>=4,15,IF(COUNTIF(Infrastructure!$A:$A,A8)>=2,10,IF(COUNTIF(Infrastructure!$A:$A,A8)>=1,5,0))) -> 10 | O8: =K8+L8+M8+N8 -> 95 | P8: =IF(O8>=70,"High",IF(O8>=50,"Medium","Watch")) -> High | Q8: Saudi Arabia expands footprint in Djibouti with major investment projects | R8: https://capitalethiopia.com/2024/07/01/saudi-arabia-expands-footprint-in-djibouti-with-major-investment-projects/ | S8: 2024-07-01
A9: Djibouti | B9: China Merchants Port Holdings Company Limited | C9: Logistics | D9: Hong Kong / Shenzhen, China | E9: China Merchants holds a 23.5% stake in the Port of Djibouti and is a key investor/co-developer in the Djibouti International Free Trade Zone (DIFTZ). | F9: China Merchants signed a deal on January 8, 2021 to fund a $3 billion expansion of Djibouti City port and DIFTZ, building on an initial $513 million phase that began October 8, 2020. | G9: 2021 | H9: $3 billion (expansion agreement); $513 million (initial phase) | I9: 3000 | J9: Distribution Center | K9: =IF(I9="",12,IF(I9>=100,40,IF(I9>=20,32,IF(I9>=5,24,IF(I9>=1,16,8))))) -> 40 | L9: =IF(G9="",5,IF(G9>=2023,25,IF(G9>=2022,20,IF(G9>=2021,14,IF(G9>=2020,8,5))))) -> 14 | M9: =IFERROR(INDEX(Methodology!$B$27:$B$36,MATCH(J9,Methodology!$A$27:$A$36,0)),12) -> 14 | N9: =IF(COUNTIF(Infrastructure!$A:$A,A9)>=4,15,IF(COUNTIF(Infrastructure!$A:$A,A9)>=2,10,IF(COUNTIF(Infrastructure!$A:$A,A9)>=1,5,0))) -> 10 | O9: =K9+L9+M9+N9 -> 78 | P9: =IF(O9>=70,"High",IF(O9>=50,"Medium","Watch")) -> High | Q9: China Merchants signs deal for $3bn expansion of Djibouti City port | R9: https://www.globalconstructionreview.com/china-merchants-signs-deal-3bn-expansion-djibouti/ | S9: 2021-01-08
A10: Djibouti | B10: PAIX Data Centres | C10: Technology | D10: Netherlands | E10: PAIX is entering Djibouti to build a cloud- and carrier-neutral data centre leveraging Djibouti's position as a landing point for roughly ten undersea cables. | F10: PAIX signed a joint-venture/MOU with the Djibouti Sovereign Wealth Fund (announced May 16, 2024) to build a ~50,000 sq ft, up to 5MW data centre, with the first phase expected to open in 2026. | G10: 2024 | H10: $50 million | I10: 50 | J10: Data Centre | K10: =IF(I10="",12,IF(I10>=100,40,IF(I10>=20,32,IF(I10>=5,24,IF(I10>=1,16,8))))) -> 32 | L10: =IF(G10="",5,IF(G10>=2023,25,IF(G10>=2022,20,IF(G10>=2021,14,IF(G10>=2020,8,5))))) -> 25 | M10: =IFERROR(INDEX(Methodology!$B$27:$B$36,MATCH(J10,Methodology!$A$27:$A$36,0)),12) -> 20 | N10: =IF(COUNTIF(Infrastructure!$A:$A,A10)>=4,15,IF(COUNTIF(Infrastructure!$A:$A,A10)>=2,10,IF(COUNTIF(Infrastructure!$A:$A,A10)>=1,5,0))) -> 10 | O10: =K10+L10+M10+N10 -> 87 | P10: =IF(O10>=70,"High",IF(O10>=50,"Medium","Watch")) -> High | Q10: PAIX to Construct Carrier-neutral Data Center in Djibouti | R10: https://www.submarinenetworks.com/en/stations/africa/djibouti/paix-to-construct-carrier-neutral-data-center-in-djibouti | S10: 2024-05-16
A11: DRC Congo | B11: CIMKO (Cimenterie Kongo) | C11: Manufacturing | D11: Songololo, Kongo-Central, DRC | E11: CIMKO operates DRC's largest integrated cement plant at Songololo, Kongo-Central, supplying the Kinshasa/western DRC market since 2018. | F11: CIMKO announced a $300m+ investment to double annual cement capacity from 1.4Mt to 3Mt by 2027, announced 5 December 2025. | G11: 2027 | H11: More than US$300 million | I11: 300 | J11: Manufacturing Plant | K11: =IF(I11="",12,IF(I11>=100,40,IF(I11>=20,32,IF(I11>=5,24,IF(I11>=1,16,8))))) -> 40 | L11: =IF(G11="",5,IF(G11>=2023,25,IF(G11>=2022,20,IF(G11>=2021,14,IF(G11>=2020,8,5))))) -> 25 | M11: =IFERROR(INDEX(Methodology!$B$27:$B$36,MATCH(J11,Methodology!$A$27:$A$36,0)),12) -> 20 | N11: =IF(COUNTIF(Infrastructure!$A:$A,A11)>=4,15,IF(COUNTIF(Infrastructure!$A:$A,A11)>=2,10,IF(COUNTIF(Infrastructure!$A:$A,A11)>=1,5,0))) -> 10 | O11: =K11+L11+M11+N11 -> 95 | P11: =IF(O11>=70,"High",IF(O11>=50,"Medium","Watch")) -> High | Q11: CIMKO to invest US$300m to double DRC cement capacity by 2027 | R11: https://www.cemnet.com/News/story/180401/cimko-to-invest-us-300m-to-double-drc-cement-capacity-by-2027.html | S11: 45265
A12: DRC Congo | B12: Africa Global Logistics (MSC Group) | C12: Logistics | D12: Geneva, Switzerland | E12: Following MSC's acquisition of Bolloré Africa Logistics, Africa Global Logistics operates freight-forwarding, dry-port and transport logistics infrastructure in DRC. | F12: MSC completed its $6.1 billion acquisition of Bolloré Africa Logistics, covering its DRC logistics operations, on 21 December 2022. | G12: 2022 | H12: US$6.1 billion (pan-African acquisition, not DRC-specific) | I12: 6100 | J12: Distribution Center | K12: =IF(I12="",12,IF(I12>=100,40,IF(I12>=20,32,IF(I12>=5,24,IF(I12>=1,16,8))))) -> 40 | L12: =IF(G12="",5,IF(G12>=2023,25,IF(G12>=2022,20,IF(G12>=2021,14,IF(G12>=2020,8,5))))) -> 20 | M12: =IFERROR(INDEX(Methodology!$B$27:$B$36,MATCH(J12,Methodology!$A$27:$A$36,0)),12) -> 14 | N12: =IF(COUNTIF(Infrastructure!$A:$A,A12)>=4,15,IF(COUNTIF(Infrastructure!$A:$A,A12)>=2,10,IF(COUNTIF(Infrastructure!$A:$A,A12)>=1,5,0))) -> 10 | O12: =K12+L12+M12+N12 -> 84 | P12: =IF(O12>=70,"High",IF(O12>=50,"Medium","Watch")) -> High | Q12: MSC Completes Acquisition of Bolloré Africa Logistics | R12: https://maritime-executive.com/article/msc-completes-acquisition-of-bollore-africa-logistics | S12: 2022-12-21
A13: DRC Congo | B13: Carrefour (via franchise partner Hyper Psaro) | C13: Retail | D13: Massy, France | E13: Carrefour entered the DRC market via a franchise partnership with Hyper Psaro, opening its first hypermarket in Kinshasa. | F13: Carrefour opened its first DRC hypermarket in Kinshasa, reported in coverage published 11 August 2025. | G13: 2025 | H13: Not disclosed | J13: Retail Store/Mall | K13: =IF(I13="",12,IF(I13>=100,40,IF(I13>=20,32,IF(I13>=5,24,IF(I13>=1,16,8))))) -> 12 | L13: =IF(G13="",5,IF(G13>=2023,25,IF(G13>=2022,20,IF(G13>=2021,14,IF(G13>=2020,8,5))))) -> 25 | M13: =IFERROR(INDEX(Methodology!$B$27:$B$36,MATCH(J13,Methodology!$A$27:$A$36,0)),12) -> 8 | N13: =IF(COUNTIF(Infrastructure!$A:$A,A13)>=4,15,IF(COUNTIF(Infrastructure!$A:$A,A13)>=2,10,IF(COUNTIF(Infrastructure!$A:$A,A13)>=1,5,0))) -> 10 | O13: =K13+L13+M13+N13 -> 55 | P13: =IF(O13>=70,"High",IF(O13>=50,"Medium","Watch")) -> Medium | Q13: First Carrefour supermarket opens in Democratic Republic of Congo | R13: https://africanmarketingconfederation.org/first-carrefour-supermarket-opens-in-democratic-republic-of-congo/ | S13: 45149
A14: DRC Congo | B14: Vodacom Congo (with Orange DRC) | C14: Technology | D14: Johannesburg, South Africa | E14: Vodacom and Orange are DRC's two largest mobile operators; together they formed a new rural towerco joint venture. | F14: Vodacom and Orange announced (14 January 2025) a joint venture to build up to 2,000 solar-powered base stations over six years to extend coverage to ~19 million people in rural DRC. | G14: 2025 | H14: Not disclosed | J14: Regional HQ / Network Infrastructure | K14: =IF(I14="",12,IF(I14>=100,40,IF(I14>=20,32,IF(I14>=5,24,IF(I14>=1,16,8))))) -> 12 | L14: =IF(G14="",5,IF(G14>=2023,25,IF(G14>=2022,20,IF(G14>=2021,14,IF(G14>=2020,8,5))))) -> 25 | M14: =IFERROR(INDEX(Methodology!$B$27:$B$36,MATCH(J14,Methodology!$A$27:$A$36,0)),12) -> 12 | N14: =IF(COUNTIF(Infrastructure!$A:$A,A14)>=4,15,IF(COUNTIF(Infrastructure!$A:$A,A14)>=2,10,IF(COUNTIF(Infrastructure!$A:$A,A14)>=1,5,0))) -> 10 | O14: =K14+L14+M14+N14 -> 59 | P14: =IF(O14>=70,"High",IF(O14>=50,"Medium","Watch")) -> Medium | Q14: Orange and Vodacom create a joint venture to expand network coverage in rural areas in the DRC | R14: https://www.vodacom.com/news-article.php?articleID=15301 | S14: 44940
A15: Eritrea | B15: Sichuan Road and Bridge Group | C15: Construction | D15: Chengdu, Sichuan, China | E15: Sichuan Road and Bridge Group acquired Australian miner Danakali's 50% stake in the Colluli potash project in Eritrea. | F15: Sichuan Road and Bridge Group completed its purchase of Danakali's 50% Colluli potash project stake, with a first $105 million instalment paid by 31 March 2023. | G15: 2023 | H15: US$105 million (first instalment) plus a further US$16 million tranche | I15: 105 | J15: Construction Project | K15: =IF(I15="",12,IF(I15>=100,40,IF(I15>=20,32,IF(I15>=5,24,IF(I15>=1,16,8))))) -> 40 | L15: =IF(G15="",5,IF(G15>=2023,25,IF(G15>=2022,20,IF(G15>=2021,14,IF(G15>=2020,8,5))))) -> 25 | M15: =IFERROR(INDEX(Methodology!$B$27:$B$36,MATCH(J15,Methodology!$A$27:$A$36,0)),12) -> 16 | N15: =IF(COUNTIF(Infrastructure!$A:$A,A15)>=4,15,IF(COUNTIF(Infrastructure!$A:$A,A15)>=2,10,IF(COUNTIF(Infrastructure!$A:$A,A15)>=1,5,0))) -> 5 | O15: =K15+L15+M15+N15 -> 86 | P15: =IF(O15>=70,"High",IF(O15>=50,"Medium","Watch")) -> High | Q15: Danakali sells stake in flagship Colluli potash project in Eritrea | R15: https://www.mining.com/danakali-sells-stake-in-flagship-colluli-potash-project-in-eritrea/ | S15: 2023-03-31
A16: Ethiopia | B16: Dangote Group | C16: Manufacturing | D16: Lagos, Nigeria | E16: Dangote has operated a cement plant in Mugher, Ethiopia since 2015 and has now signed a joint venture with Ethiopian Investment Holdings to build one of the world's largest fertiliser plants in Gode. | F16: Signed a JV (Dangote 60% / Ethiopian Investment Holdings 40%) to build a $2.5B fertiliser plant in Gode, southeast Ethiopia, targeting ~3 million tonnes/year production; signed August 29, 2025. | G16: 2025 | H16: $2.5 billion | I16: 2500 | J16: Manufacturing Plant | K16: =IF(I16="",12,IF(I16>=100,40,IF(I16>=20,32,IF(I16>=5,24,IF(I16>=1,16,8))))) -> 40 | L16: =IF(G16="",5,IF(G16>=2023,25,IF(G16>=2022,20,IF(G16>=2021,14,IF(G16>=2020,8,5))))) -> 25 | M16: =IFERROR(INDEX(Methodology!$B$27:$B$36,MATCH(J16,Methodology!$A$27:$A$36,0)),12) -> 20 | N16: =IF(COUNTIF(Infrastructure!$A:$A,A16)>=4,15,IF(COUNTIF(Infrastructure!$A:$A,A16)>=2,10,IF(COUNTIF(Infrastructure!$A:$A,A16)>=1,5,0))) -> 15 | O16: =K16+L16+M16+N16 -> 100 | P16: =IF(O16>=70,"High",IF(O16>=50,"Medium","Watch")) -> High | Q16: Nigeria: Dangote Group, Ethiopia Sign Deal to Build $2.5bn Fertiliser Plant | R16: https://allafrica.com/stories/202508290063.html | S16: August 29, 2023
A17: Ethiopia | B17: Komari Beverage (Arada) — acquired by Heineken N.V. | C17: Manufacturing | D17: Amhara Region, Ethiopia (parent: Heineken N.V., Amsterdam, Netherlands) | E17: Heineken has operated breweries in Ethiopia since 2011 (Kilinto, Harar, Bedele) as part of a EUR310M+ cumulative investment, and diversified via acquisition into the local spirits/hard-seltzer category. | F17: Acquired ownership of the Arada hard-seltzer brand from Ethiopian producer Komari Beverage (which built a $29M+ factory in Amhara region); deal concluded mid-October 2024. | G17: 2024 | H17: Not disclosed | J17: Manufacturing Plant | K17: =IF(I17="",12,IF(I17>=100,40,IF(I17>=20,32,IF(I17>=5,24,IF(I17>=1,16,8))))) -> 12 | L17: =IF(G17="",5,IF(G17>=2023,25,IF(G17>=2022,20,IF(G17>=2021,14,IF(G17>=2020,8,5))))) -> 25 | M17: =IFERROR(INDEX(Methodology!$B$27:$B$36,MATCH(J17,Methodology!$A$27:$A$36,0)),12) -> 20 | N17: =IF(COUNTIF(Infrastructure!$A:$A,A17)>=4,15,IF(COUNTIF(Infrastructure!$A:$A,A17)>=2,10,IF(COUNTIF(Infrastructure!$A:$A,A17)>=1,5,0))) -> 15 | O17: =K17+L17+M17+N17 -> 72 | P17: =IF(O17>=70,"High",IF(O17>=50,"Medium","Watch")) -> High | Q17: Heineken acquires Komari Beverage | R17: https://capitalethiopia.com/2024/10/14/heineken-acquires-komari-beverage/ | S17: October 14, 2024
A18: Ethiopia | B18: TOYO Co., Ltd (TOYO Solar) | C18: Manufacturing | D18: Tokyo, Japan (with production also in Vietnam) | E18: Built its first East African manufacturing base inside Hawassa's special economic zone, using Ethiopia's largely hydropower-based grid to supply its US solar module plant. | F18: Began commercial production at its 2GW (expanding to 4GW) TOPCon solar cell plant in Hawassa; production start April 2025. | G18: 2025 | H18: $60 million (initial phase) | I18: 60 | J18: Manufacturing Plant | K18: =IF(I18="",12,IF(I18>=100,40,IF(I18>=20,32,IF(I18>=5,24,IF(I18>=1,16,8))))) -> 32 | L18: =IF(G18="",5,IF(G18>=2023,25,IF(G18>=2022,20,IF(G18>=2021,14,IF(G18>=2020,8,5))))) -> 25 | M18: =IFERROR(INDEX(Methodology!$B$27:$B$36,MATCH(J18,Methodology!$A$27:$A$36,0)),12) -> 20 | N18: =IF(COUNTIF(Infrastructure!$A:$A,A18)>=4,15,IF(COUNTIF(Infrastructure!$A:$A,A18)>=2,10,IF(COUNTIF(Infrastructure!$A:$A,A18)>=1,5,0))) -> 15 | O18: =K18+L18+M18+N18 -> 92 | P18: =IF(O18>=70,"High",IF(O18>=50,"Medium","Watch")) -> High | Q18: Japan's Toyo begins production at 2 GW solar cell plant in Ethiopia | R18: https://www.pv-magazine.com/2025/04/23/japans-toyo-begins-production-at-2-gw-solar-cell-plant-in-ethiopia/ | S18: April 23, 2023
A19: Ethiopia | B19: DHL Group | C19: Logistics | D19: Bonn, Germany | E19: DHL Express operates in Ethiopia and was explicitly named alongside Nigeria as a priority market for gateway and aviation-capacity upgrades under DHL's new Africa investment plan. | F19: Announced EUR300M+ investment across sub-Saharan Africa, citing recent growth in Ethiopia and Nigeria and plans to upgrade gateways, add aviation uplift, and expand into second-tier cities; announced October 15, 2025. | G19: 2025 | H19: EUR300 million+ (regional; Ethiopia-specific allocation not disclosed) | J19: Distribution Center | K19: =IF(I19="",12,IF(I19>=100,40,IF(I19>=20,32,IF(I19>=5,24,IF(I19>=1,16,8))))) -> 12 | L19: =IF(G19="",5,IF(G19>=2023,25,IF(G19>=2022,20,IF(G19>=2021,14,IF(G19>=2020,8,5))))) -> 25 | M19: =IFERROR(INDEX(Methodology!$B$27:$B$36,MATCH(J19,Methodology!$A$27:$A$36,0)),12) -> 14 | N19: =IF(COUNTIF(Infrastructure!$A:$A,A19)>=4,15,IF(COUNTIF(Infrastructure!$A:$A,A19)>=2,10,IF(COUNTIF(Infrastructure!$A:$A,A19)>=1,5,0))) -> 15 | O19: =K19+L19+M19+N19 -> 66 | P19: =IF(O19>=70,"High",IF(O19>=50,"Medium","Watch")) -> Medium | Q19: DHL Group commits more than EUR300 million to accelerate trade growth across Africa | R19: https://group.dhl.com/en/media-relations/press-releases/2025/dhl-group-commits-more-than-300-million-to-accelerate-trade-growth-across-africa.html | S19: October 15, 2023
A20: Ethiopia | B20: Ethiopian Airlines Group | C20: Logistics | D20: Addis Ababa, Ethiopia | E20: Africa's largest airline/cargo group, operating from its Bole hub with a continent-wide freight network. | F20: Opened a new $55M e-commerce/cargo sorting hub at Bole International Airport built to serve Alibaba and Shein, with 150,000-tonne annual capacity; inaugurated February 29, 2024. | G20: 2024 | H20: $55 million | I20: 55 | J20: Distribution Center | K20: =IF(I20="",12,IF(I20>=100,40,IF(I20>=20,32,IF(I20>=5,24,IF(I20>=1,16,8))))) -> 32 | L20: =IF(G20="",5,IF(G20>=2023,25,IF(G20>=2022,20,IF(G20>=2021,14,IF(G20>=2020,8,5))))) -> 25 | M20: =IFERROR(INDEX(Methodology!$B$27:$B$36,MATCH(J20,Methodology!$A$27:$A$36,0)),12) -> 14 | N20: =IF(COUNTIF(Infrastructure!$A:$A,A20)>=4,15,IF(COUNTIF(Infrastructure!$A:$A,A20)>=2,10,IF(COUNTIF(Infrastructure!$A:$A,A20)>=1,5,0))) -> 15 | O20: =K20+L20+M20+N20 -> 86 | P20: =IF(O20>=70,"High",IF(O20>=50,"Medium","Watch")) -> High | Q20: Ethiopian Airlines Opens $55 Million Cargo Center At Addis Ababa Airport | R20: https://simpleflying.com/ethiopian-airlines-55-million-cargo-center-addis-ababa-airport/ | S20: February 2024
A21: Ethiopia | B21: Queens Supermarket PLC (Midroc Investment Group) — Carrefour franchise partner | C21: Retail | D21: Addis Ababa, Ethiopia (franchise partner of Carrefour Group, Massy, France) | E21: New market entrant; franchise agreement with Queens Supermarket PLC (a Midroc Investment Group subsidiary) will rebrand Queens' 13 existing stores and add new locations. | F21: Signed a franchise deal with Queens Supermarket/Midroc to enter Ethiopia - first Carrefour-branded stores from Q1 2026, with 17 additional stores planned by 2028; announced January 2026, following Ethiopia's opening of retail to foreign investment. | G21: 2026 | H21: Not disclosed | J21: Retail Store/Mall | K21: =IF(I21="",12,IF(I21>=100,40,IF(I21>=20,32,IF(I21>=5,24,IF(I21>=1,16,8))))) -> 12 | L21: =IF(G21="",5,IF(G21>=2023,25,IF(G21>=2022,20,IF(G21>=2021,14,IF(G21>=2020,8,5))))) -> 25 | M21: =IFERROR(INDEX(Methodology!$B$27:$B$36,MATCH(J21,Methodology!$A$27:$A$36,0)),12) -> 8 | N21: =IF(COUNTIF(Infrastructure!$A:$A,A21)>=4,15,IF(COUNTIF(Infrastructure!$A:$A,A21)>=2,10,IF(COUNTIF(Infrastructure!$A:$A,A21)>=1,5,0))) -> 15 | O21: =K21+L21+M21+N21 -> 60 | P21: =IF(O21>=70,"High",IF(O21>=50,"Medium","Watch")) -> Medium | Q21: Carrefour's entry marks a new era for foreign investment in the retail sector | R21: https://capitalethiopia.com/2026/01/11/carrefours-entry-marks-a-new-era-for-foreign-investment-in-the-retail-sector/ | S21: January 11, 2026
A22: Ethiopia | B22: Roha Group (Roha Medical Campus) | C22: Pharma | D22: United States | E22: Building Ethiopia's first JCI-accredited, 350-bed multispecialty hospital in Addis Ababa, positioned as the anchor of a planned African medical-tourism hub. | F22: Received first $42M equity tranche (of a $130M Phase 1) to fund construction of Roha Medical Campus hospital near Bole International Airport; announced February 22, 2024. | G22: 2024 | H22: $42 million (initial tranche; $130M Phase 1 total) | I22: 42 | J22: Hospital/Pharma Plant | K22: =IF(I22="",12,IF(I22>=100,40,IF(I22>=20,32,IF(I22>=5,24,IF(I22>=1,16,8))))) -> 32 | L22: =IF(G22="",5,IF(G22>=2023,25,IF(G22>=2022,20,IF(G22>=2021,14,IF(G22>=2020,8,5))))) -> 25 | M22: =IFERROR(INDEX(Methodology!$B$27:$B$36,MATCH(J22,Methodology!$A$27:$A$36,0)),12) -> 18 | N22: =IF(COUNTIF(Infrastructure!$A:$A,A22)>=4,15,IF(COUNTIF(Infrastructure!$A:$A,A22)>=2,10,IF(COUNTIF(Infrastructure!$A:$A,A22)>=1,5,0))) -> 15 | O22: =K22+L22+M22+N22 -> 90 | P22: =IF(O22>=70,"High",IF(O22>=50,"Medium","Watch")) -> High | Q22: Roha Medical Campus, a World-Class Hospital in Ethiopia, Gets $42 Million First Injection | R22: https://www.businesswire.com/news/home/20240222253596/en/Roha-Medical-Campus-a-World-Class-Hospital-in-Ethiopia-Gets-$42-Million-First-Injection | S22: February 22, 2024
A23: Ethiopia | B23: TechInvention Lifecare | C23: Pharma | D23: Mumbai, India | E23: New advisory partnership with Ethiopia's Ministry of Health to design the country's first local vaccine-manufacturing facility. | F23: Signed agreement with Ethiopia's Ministry of Health for feasibility studies, facility design, and technology-transfer support for a national vaccine plant; signed January 7, 2025, Addis Ababa. | G23: 2025 | H23: Not disclosed | J23: Hospital/Pharma Plant | K23: =IF(I23="",12,IF(I23>=100,40,IF(I23>=20,32,IF(I23>=5,24,IF(I23>=1,16,8))))) -> 12 | L23: =IF(G23="",5,IF(G23>=2023,25,IF(G23>=2022,20,IF(G23>=2021,14,IF(G23>=2020,8,5))))) -> 25 | M23: =IFERROR(INDEX(Methodology!$B$27:$B$36,MATCH(J23,Methodology!$A$27:$A$36,0)),12) -> 18 | N23: =IF(COUNTIF(Infrastructure!$A:$A,A23)>=4,15,IF(COUNTIF(Infrastructure!$A:$A,A23)>=2,10,IF(COUNTIF(Infrastructure!$A:$A,A23)>=1,5,0))) -> 15 | O23: =K23+L23+M23+N23 -> 70 | P23: =IF(O23>=70,"High",IF(O23>=50,"Medium","Watch")) -> High | Q23: TechInvention Joins Hands with Ethiopia to Boost Vaccine Manufacturing and Pandemic Preparedness | R23: https://ehealth.eletsonline.com/2025/01/techinvention-joins-hands-with-ethiopia-to-boost-vaccine-manufacturing-and-pandemic-preparedness/ | S23: 44927
A24: Ethiopia | B24: EagleLion System Technology (StarPay Financial Services / Choice Microfinance) — Mastercard partner | C24: Technology | D24: Addis Ababa, Ethiopia (partner network for Mastercard, Purchase, New York, USA) | E24: Expanding Ethiopian payments footprint through local fintech partnerships as the country's digital-payments market opens up. | F24: Signed dual strategic partnerships with StarPay Financial Services (reseller/distributor of Mastercard products) and Choice Microfinance (digital credit for underserved segments), both EagleLion subsidiaries; announced April 11, 2026. | G24: 2026 | H24: Not disclosed | J24: Regional HQ | K24: =IF(I24="",12,IF(I24>=100,40,IF(I24>=20,32,IF(I24>=5,24,IF(I24>=1,16,8))))) -> 12 | L24: =IF(G24="",5,IF(G24>=2023,25,IF(G24>=2022,20,IF(G24>=2021,14,IF(G24>=2020,8,5))))) -> 25 | M24: =IFERROR(INDEX(Methodology!$B$27:$B$36,MATCH(J24,Methodology!$A$27:$A$36,0)),12) -> 10 | N24: =IF(COUNTIF(Infrastructure!$A:$A,A24)>=4,15,IF(COUNTIF(Infrastructure!$A:$A,A24)>=2,10,IF(COUNTIF(Infrastructure!$A:$A,A24)>=1,5,0))) -> 15 | O24: =K24+L24+M24+N24 -> 62 | P24: =IF(O24>=70,"High",IF(O24>=50,"Medium","Watch")) -> Medium | Q24: Mastercard expands footprint through dual strategic partnerships | R24: https://capitalethiopia.com/2026/04/11/mastercard-expands-footprint-through-dual-strategic-partnerships/ | S24: April 11, 2023
A25: Ethiopia | B25: Raxio Group | C25: Technology | D25: Kampala, Uganda | E25: Pan-African data centre operator (Uganda, DRC, Mozambique, Cote d'Ivoire) that entered Ethiopia with its flagship East African facility. | F25: Launched ET1, a Tier III, 3MW/800-rack data centre in Addis Ababa's Ethio ICT Park; opened November 2023. | G25: 2023 | H25: Not disclosed | J25: Data Centre | K25: =IF(I25="",12,IF(I25>=100,40,IF(I25>=20,32,IF(I25>=5,24,IF(I25>=1,16,8))))) -> 12 | L25: =IF(G25="",5,IF(G25>=2023,25,IF(G25>=2022,20,IF(G25>=2021,14,IF(G25>=2020,8,5))))) -> 25 | M25: =IFERROR(INDEX(Methodology!$B$27:$B$36,MATCH(J25,Methodology!$A$27:$A$36,0)),12) -> 20 | N25: =IF(COUNTIF(Infrastructure!$A:$A,A25)>=4,15,IF(COUNTIF(Infrastructure!$A:$A,A25)>=2,10,IF(COUNTIF(Infrastructure!$A:$A,A25)>=1,5,0))) -> 15 | O25: =K25+L25+M25+N25 -> 72 | P25: =IF(O25>=70,"High",IF(O25>=50,"Medium","Watch")) -> High | Q25: Raxio launches data center in Addis Ababa, Ethiopia | R25: https://www.datacenterdynamics.com/en/news/raxio-launches-data-center-in-addis-ababa-ethiopia/ | S25: November 2023
A26: Ethiopia | B26: Safaricom Ethiopia (Safaricom PLC / Vodacom-Vodafone consortium) | C26: Technology | D26: Nairobi, Kenya | E26: Ethiopia's first competing mobile network operator since license launch in 2022; passed 10 million active customers by mid-2025 and continues nationwide network buildout. | F26: Secured a $138M syndicated loan from Standard Bank Group for continued Ethiopian network expansion; announced December 11, 2025. | G26: 2025 | H26: $138 million | I26: 138 | J26: Regional HQ / Network Infrastructure | K26: =IF(I26="",12,IF(I26>=100,40,IF(I26>=20,32,IF(I26>=5,24,IF(I26>=1,16,8))))) -> 40 | L26: =IF(G26="",5,IF(G26>=2023,25,IF(G26>=2022,20,IF(G26>=2021,14,IF(G26>=2020,8,5))))) -> 25 | M26: =IFERROR(INDEX(Methodology!$B$27:$B$36,MATCH(J26,Methodology!$A$27:$A$36,0)),12) -> 12 | N26: =IF(COUNTIF(Infrastructure!$A:$A,A26)>=4,15,IF(COUNTIF(Infrastructure!$A:$A,A26)>=2,10,IF(COUNTIF(Infrastructure!$A:$A,A26)>=1,5,0))) -> 15 | O26: =K26+L26+M26+N26 -> 92 | P26: =IF(O26>=70,"High",IF(O26>=50,"Medium","Watch")) -> High | Q26: Standard Bank, led by Sim Tshabalala, backs Safaricom Ethiopia with $138 million funding push | R26: https://www.billionaires.africa/2025/12/11/standard-bank-safaricom-ethiopia-138m-funding/ | S26: December 11, 2023
A27: Ethiopia | B27: China Civil Engineering Construction Corporation (CCECC) | C27: Construction | D27: Beijing, China | E27: Longtime Ethiopian infrastructure contractor (Addis Ababa-Djibouti railway, Hawassa & Dire Dawa industrial parks, Modjo dry port expansion); now building a new special economic zone. | F27: Broke ground on the Lume Free Trade Zone within the new Gada Special Economic Zone in Oromia (~65km SE of Addis Ababa), Ethiopia's second free trade zone; groundbreaking May 10, 2024. | G27: 2024 | H27: Not disclosed | J27: Construction Project | K27: =IF(I27="",12,IF(I27>=100,40,IF(I27>=20,32,IF(I27>=5,24,IF(I27>=1,16,8))))) -> 12 | L27: =IF(G27="",5,IF(G27>=2023,25,IF(G27>=2022,20,IF(G27>=2021,14,IF(G27>=2020,8,5))))) -> 25 | M27: =IFERROR(INDEX(Methodology!$B$27:$B$36,MATCH(J27,Methodology!$A$27:$A$36,0)),12) -> 16 | N27: =IF(COUNTIF(Infrastructure!$A:$A,A27)>=4,15,IF(COUNTIF(Infrastructure!$A:$A,A27)>=2,10,IF(COUNTIF(Infrastructure!$A:$A,A27)>=1,5,0))) -> 15 | O27: =K27+L27+M27+N27 -> 68 | P27: =IF(O27>=70,"High",IF(O27>=50,"Medium","Watch")) -> Medium | Q27: Ethiopia launches construction of Chinese-contracted economic zone | R27: https://eng.yidaiyilu.gov.cn/p/0M376K98.html | S27: May 10, 2024
A28: Kenya | B28: Amsons Industries (K) Ltd (Amsons Group) | C28: Manufacturing | D28: Dar es Salaam, Tanzania | E28: Amsons Group is a Tanzanian family-owned conglomerate active in cement, bulk petroleum, wheat milling and LPG across Tanzania, Burundi, DR Congo, Mozambique and Zambia, generating over $1 billion in annual turnover; its Kenyan subsidiary Amsons Industries (K) Ltd is moving to take control of Bamburi Cement, Kenya's largest cement producer. | F28: Launched a mandatory buyout offer for all shares of Bamburi Cement Plc at KSh65/share (a 44% premium), a deal valued at roughly KSh 23.59 billion, to acquire Holcim's 58.6% stake and delist Bamburi from the Nairobi Securities Exchange; announced July 15, 2024. | G28: 2024 | H28: KSh 23.59 billion (~US$180 million) | I28: 180 | J28: Manufacturing Plant | K28: =IF(I28="",12,IF(I28>=100,40,IF(I28>=20,32,IF(I28>=5,24,IF(I28>=1,16,8))))) -> 40 | L28: =IF(G28="",5,IF(G28>=2023,25,IF(G28>=2022,20,IF(G28>=2021,14,IF(G28>=2020,8,5))))) -> 25 | M28: =IFERROR(INDEX(Methodology!$B$27:$B$36,MATCH(J28,Methodology!$A$27:$A$36,0)),12) -> 20 | N28: =IF(COUNTIF(Infrastructure!$A:$A,A28)>=4,15,IF(COUNTIF(Infrastructure!$A:$A,A28)>=2,10,IF(COUNTIF(Infrastructure!$A:$A,A28)>=1,5,0))) -> 15 | O28: =K28+L28+M28+N28 -> 100 | P28: =IF(O28>=70,"High",IF(O28>=50,"Medium","Watch")) -> High | Q28: Inside Amsons Group's KShs 23.59bn Buyout Offer for Bamburi Cement | R28: https://kenyanwallstreet.com/inside-amsons-group-kshs-23-59bn-buyout-offer-for-bamburi-cement/ | S28: July 15, 2024
A29: Kenya | B29: Devki Group (Simba Cement) | C29: Manufacturing | D29: Nairobi, Kenya | E29: Major Kenyan industrial conglomerate producing cement and steel, with operations spanning Kenya, Uganda, DRC, Rwanda and Zambia. | F29: Launched the Cemtech Sebit Clinkerization Plant in West Pokot on April 8, 2024 - a 2-million-tonne-per-year clinker facility ending Kenya's reliance on imported clinker. | G29: 2024 | H29: $220 million (approx. Sh29 billion) | I29: 220 | J29: Manufacturing Plant | K29: =IF(I29="",12,IF(I29>=100,40,IF(I29>=20,32,IF(I29>=5,24,IF(I29>=1,16,8))))) -> 40 | L29: =IF(G29="",5,IF(G29>=2023,25,IF(G29>=2022,20,IF(G29>=2021,14,IF(G29>=2020,8,5))))) -> 25 | M29: =IFERROR(INDEX(Methodology!$B$27:$B$36,MATCH(J29,Methodology!$A$27:$A$36,0)),12) -> 20 | N29: =IF(COUNTIF(Infrastructure!$A:$A,A29)>=4,15,IF(COUNTIF(Infrastructure!$A:$A,A29)>=2,10,IF(COUNTIF(Infrastructure!$A:$A,A29)>=1,5,0))) -> 15 | O29: =K29+L29+M29+N29 -> 100 | P29: =IF(O29>=70,"High",IF(O29>=50,"Medium","Watch")) -> High | Q29: Devki Opens Sh29bn Clinker Factory in West Pokot | R29: https://www.constructionkenya.com/2941/pokot-cement-factory/ | S29: April 8, 2024
A30: Kenya | B30: Kenya Vehicle Manufacturers (KVM) — Volkswagen assembly partner | C30: Manufacturing | D30: Thika, Kenya (local assembly partner; Volkswagen AG HQ Wolfsburg, Germany) | E30: Assembles vehicles in Kenya through local partner Kenya Vehicle Manufacturers (KVM) in Thika. | F30: Resumed local vehicle assembly (Polo Vivo) at the KVM Thika plant in August 2025, restarting Volkswagen production in Kenya after roughly four decades, targeting about 5,000 units per year. | G30: 2025 | H30: Not disclosed | J30: Manufacturing Plant | K30: =IF(I30="",12,IF(I30>=100,40,IF(I30>=20,32,IF(I30>=5,24,IF(I30>=1,16,8))))) -> 12 | L30: =IF(G30="",5,IF(G30>=2023,25,IF(G30>=2022,20,IF(G30>=2021,14,IF(G30>=2020,8,5))))) -> 25 | M30: =IFERROR(INDEX(Methodology!$B$27:$B$36,MATCH(J30,Methodology!$A$27:$A$36,0)),12) -> 20 | N30: =IF(COUNTIF(Infrastructure!$A:$A,A30)>=4,15,IF(COUNTIF(Infrastructure!$A:$A,A30)>=2,10,IF(COUNTIF(Infrastructure!$A:$A,A30)>=1,5,0))) -> 15 | O30: =K30+L30+M30+N30 -> 72 | P30: =IF(O30>=70,"High",IF(O30>=50,"Medium","Watch")) -> High | Q30: Kenya's motor assembler resumes Volkswagen production | R30: https://www.the-star.co.ke/business/2025-08-22-kenya-motor-assembler-resumes-volkswagen-production | S30: August 22, 2025
A31: Kenya | B31: Milly Group (Milly Glass SEZ Limited) | C31: Manufacturing | D31: Mombasa, Kenya | E31: Kenyan group also operating a juice-processing factory in Malindi; new subsidiary building what is billed as Africa's first amber pharmaceutical-glass-bottle plant, serving Kenya, Tanzania, Uganda, Rwanda, Burundi and the wider COMESA region. | F31: Groundbreaking planned for end of August 2026 on an 80-tonne glass factory (15 acres) inside the Dongo Kundu SEZ, Mombasa, to produce ~300,000 pharmaceutical bottles; production targeted for July 2027. | G31: 2026 | H31: Not disclosed | J31: Manufacturing Plant | K31: =IF(I31="",12,IF(I31>=100,40,IF(I31>=20,32,IF(I31>=5,24,IF(I31>=1,16,8))))) -> 12 | L31: =IF(G31="",5,IF(G31>=2023,25,IF(G31>=2022,20,IF(G31>=2021,14,IF(G31>=2020,8,5))))) -> 25 | M31: =IFERROR(INDEX(Methodology!$B$27:$B$36,MATCH(J31,Methodology!$A$27:$A$36,0)),12) -> 20 | N31: =IF(COUNTIF(Infrastructure!$A:$A,A31)>=4,15,IF(COUNTIF(Infrastructure!$A:$A,A31)>=2,10,IF(COUNTIF(Infrastructure!$A:$A,A31)>=1,5,0))) -> 15 | O31: =K31+L31+M31+N31 -> 72 | P31: =IF(O31>=70,"High",IF(O31>=50,"Medium","Watch")) -> High | Q31: Kenyan firm to be first maker of pharmaceutical bottles in Africa | R31: https://www.the-star.co.ke/counties/coast/2026-07-25-kenyan-firm-to-be-first-maker-of-pharmaceutical-bottles-in-africa | S31: July 25, 2026
A32: Kenya | B32: DHL | C32: Logistics | D32: Bonn, Germany | E32: Major express/logistics operator in Kenya, positioning Nairobi as a rising African gateway comparable to South Africa. | F32: Announced a new carbon-neutral regional headquarters building in Nairobi as part of a EUR300 million (~Sh45 billion), five-year pan-African investment plan spanning e-commerce, perishables, energy and life-sciences logistics (reported October 2025). | G32: 2025 | H32: EUR300 million (Africa-wide five-year plan; Kenya-specific allocation not disclosed) | J32: Regional HQ | K32: =IF(I32="",12,IF(I32>=100,40,IF(I32>=20,32,IF(I32>=5,24,IF(I32>=1,16,8))))) -> 12 | L32: =IF(G32="",5,IF(G32>=2023,25,IF(G32>=2022,20,IF(G32>=2021,14,IF(G32>=2020,8,5))))) -> 25 | M32: =IFERROR(INDEX(Methodology!$B$27:$B$36,MATCH(J32,Methodology!$A$27:$A$36,0)),12) -> 10 | N32: =IF(COUNTIF(Infrastructure!$A:$A,A32)>=4,15,IF(COUNTIF(Infrastructure!$A:$A,A32)>=2,10,IF(COUNTIF(Infrastructure!$A:$A,A32)>=1,5,0))) -> 15 | O32: =K32+L32+M32+N32 -> 62 | P32: =IF(O32>=70,"High",IF(O32>=50,"Medium","Watch")) -> Medium | Q32: DHL eyes new Nairobi office in Sh45 billion Africa expansion bid | R32: https://www.businessdailyafrica.com/bd/corporate/companies/dhl-eyes-new-nairobi-office-in-sh45bn-africa-expansion-bid-5233152 | S32: October 2025
A33: Kenya | B33: DP World | C33: Logistics | D33: Dubai, UAE | E33: Operates container terminal services at the Port of Mombasa and is expanding into inland industrial/logistics real estate near the port. | F33: Signed an agreement with GulfCap Africa (August 2026) to co-develop a 222-hectare Mombasa Industrial Park special economic zone within 20km of the Port of Mombasa, for manufacturers, logistics providers and regional distribution businesses. | G33: 2026 | H33: Not disclosed | J33: Distribution Center | K33: =IF(I33="",12,IF(I33>=100,40,IF(I33>=20,32,IF(I33>=5,24,IF(I33>=1,16,8))))) -> 12 | L33: =IF(G33="",5,IF(G33>=2023,25,IF(G33>=2022,20,IF(G33>=2021,14,IF(G33>=2020,8,5))))) -> 25 | M33: =IFERROR(INDEX(Methodology!$B$27:$B$36,MATCH(J33,Methodology!$A$27:$A$36,0)),12) -> 14 | N33: =IF(COUNTIF(Infrastructure!$A:$A,A33)>=4,15,IF(COUNTIF(Infrastructure!$A:$A,A33)>=2,10,IF(COUNTIF(Infrastructure!$A:$A,A33)>=1,5,0))) -> 15 | O33: =K33+L33+M33+N33 -> 66 | P33: =IF(O33>=70,"High",IF(O33>=50,"Medium","Watch")) -> Medium | Q33: DP World to co-develop free zone in Kenya | R33: https://www.agbi.com/logistics/2026/08/dp-world-to-co-develop-free-zone-in-kenya/ | S33: August 2026
A34: Kenya | B34: Majid Al Futtaim (Carrefour) | C34: Retail | D34: Dubai, UAE | E34: Kenya's largest hypermarket operator under the Carrefour franchise, growing to 34 outlets nationwide with over 2,800 direct employees by 2025. | F34: Opened its 30th Carrefour store in Kenya at Waris Mall, Ruai (1,500 sqm, ~40 jobs) by September 2025, part of eight new store openings that year. | G34: 2025 | H34: Not disclosed | J34: Retail Store/Mall | K34: =IF(I34="",12,IF(I34>=100,40,IF(I34>=20,32,IF(I34>=5,24,IF(I34>=1,16,8))))) -> 12 | L34: =IF(G34="",5,IF(G34>=2023,25,IF(G34>=2022,20,IF(G34>=2021,14,IF(G34>=2020,8,5))))) -> 25 | M34: =IFERROR(INDEX(Methodology!$B$27:$B$36,MATCH(J34,Methodology!$A$27:$A$36,0)),12) -> 8 | N34: =IF(COUNTIF(Infrastructure!$A:$A,A34)>=4,15,IF(COUNTIF(Infrastructure!$A:$A,A34)>=2,10,IF(COUNTIF(Infrastructure!$A:$A,A34)>=1,5,0))) -> 15 | O34: =K34+L34+M34+N34 -> 60 | P34: =IF(O34>=70,"High",IF(O34>=50,"Medium","Watch")) -> Medium | Q34: Majid Al Futtaim Opens 30th Carrefour Store in Kenya, Creates 40 Jobs | R34: https://www.eabusinesstimes.com/majid-al-futtaim-opens-30th-carrefour-store-in-kenya-creates-40-jobs/ | S34: 2025
A35: Kenya | B35: Naivas Limited | C35: Retail | D35: Nairobi, Kenya | E35: Kenya's largest homegrown supermarket chain; FY2025 revenue $751.4 million (+21.6% YoY), net profit $16.1 million (+43.4% YoY). | F35: Opened its 112th store in Mihango, Nairobi (announced December 2025), part of a plan to add up to 10 stores per year toward a 200-store target. | G35: 2025 | H35: Not disclosed | J35: Retail Store/Mall | K35: =IF(I35="",12,IF(I35>=100,40,IF(I35>=20,32,IF(I35>=5,24,IF(I35>=1,16,8))))) -> 12 | L35: =IF(G35="",5,IF(G35>=2023,25,IF(G35>=2022,20,IF(G35>=2021,14,IF(G35>=2020,8,5))))) -> 25 | M35: =IFERROR(INDEX(Methodology!$B$27:$B$36,MATCH(J35,Methodology!$A$27:$A$36,0)),12) -> 8 | N35: =IF(COUNTIF(Infrastructure!$A:$A,A35)>=4,15,IF(COUNTIF(Infrastructure!$A:$A,A35)>=2,10,IF(COUNTIF(Infrastructure!$A:$A,A35)>=1,5,0))) -> 15 | O35: =K35+L35+M35+N35 -> 60 | P35: =IF(O35>=70,"High",IF(O35>=50,"Medium","Watch")) -> Medium | Q35: Carrefour and Naivas drive Kenya's retail expansion | R35: https://khusoko.com/2025/12/16/carrefour-and-naivas-drive-kenyas-retail-expansion/ | S35: December 16, 2025
A36: Kenya | B36: Crown Healthcare | C36: Pharma | D36: Nairobi, Kenya | E36: Kenyan healthcare distributor expanding into pharmaceutical manufacturing, with distribution reach into Nigeria, Tanzania, Uganda and Rwanda. | F36: Secured $10 million from Impact Fund Denmark (announced December 15, 2025) to build a large-scale generic-medicines manufacturing plant, expected to create about 600 jobs, cutting reliance on Kenya's ~80% imported medicines. | G36: 2025 | H36: $10 million | I36: 10 | J36: Hospital/Pharma Plant | K36: =IF(I36="",12,IF(I36>=100,40,IF(I36>=20,32,IF(I36>=5,24,IF(I36>=1,16,8))))) -> 24 | L36: =IF(G36="",5,IF(G36>=2023,25,IF(G36>=2022,20,IF(G36>=2021,14,IF(G36>=2020,8,5))))) -> 25 | M36: =IFERROR(INDEX(Methodology!$B$27:$B$36,MATCH(J36,Methodology!$A$27:$A$36,0)),12) -> 18 | N36: =IF(COUNTIF(Infrastructure!$A:$A,A36)>=4,15,IF(COUNTIF(Infrastructure!$A:$A,A36)>=2,10,IF(COUNTIF(Infrastructure!$A:$A,A36)>=1,5,0))) -> 15 | O36: =K36+L36+M36+N36 -> 82 | P36: =IF(O36>=70,"High",IF(O36>=50,"Medium","Watch")) -> High | Q36: Kenyan entrepreneur Shilen Thakerar's Crown Healthcare to build new pharma plant with $10 million | R36: https://www.billionaires.africa/2025/12/15/kenyan-entrepreneur-shilen-thakerars-crown-healthcare-to-build-new-pharma-plant-with-10-million/ | S36: December 15, 2025
A37: Kenya | B37: Amazon Web Services (AWS) | C37: Technology | D37: Seattle, USA | E37: Operates a Nairobi-based Development Centre - AWS's second in Africa after Cape Town - housing R&D, cloud support and software engineering teams. | F37: Launched its second African Development Centre on Riverside Drive, Nairobi, October 5, 2023. | G37: 2023 | H37: Not disclosed | J37: R&D Centre | K37: =IF(I37="",12,IF(I37>=100,40,IF(I37>=20,32,IF(I37>=5,24,IF(I37>=1,16,8))))) -> 12 | L37: =IF(G37="",5,IF(G37>=2023,25,IF(G37>=2022,20,IF(G37>=2021,14,IF(G37>=2020,8,5))))) -> 25 | M37: =IFERROR(INDEX(Methodology!$B$27:$B$36,MATCH(J37,Methodology!$A$27:$A$36,0)),12) -> 14 | N37: =IF(COUNTIF(Infrastructure!$A:$A,A37)>=4,15,IF(COUNTIF(Infrastructure!$A:$A,A37)>=2,10,IF(COUNTIF(Infrastructure!$A:$A,A37)>=1,5,0))) -> 15 | O37: =K37+L37+M37+N37 -> 66 | P37: =IF(O37>=70,"High",IF(O37>=50,"Medium","Watch")) -> Medium | Q37: AWS Launches its second African Development Centre in Kenya | R37: https://techtrendske.co.ke/2023/10/05/aws-launches-its-second-african-development-centre-in-kenya/ | S37: October 5, 2023
A38: Kenya | B38: Huawei Technologies | C38: Technology | D38: Shenzhen, China | E38: Huawei has operated in Kenya for over two decades, partnering with the Kenyan government on national ICT infrastructure, most notably building the Konza Technopolis National Cloud Data Centre and Government Cloud alongside network infrastructure for local telecom operators. | F38: Committed to build a National Cloud data centre, smart ICT/surveillance systems and a Government Cloud at Konza Technopolis, financed via Chinese concessional loans; Phase 1 (containerized National Data Centre) completed July 2020, valued at KSh 17.5 billion. | G38: 2020 | H38: KSh 17.5 billion (~US$173 million) | I38: 173 | J38: Data Centre | K38: =IF(I38="",12,IF(I38>=100,40,IF(I38>=20,32,IF(I38>=5,24,IF(I38>=1,16,8))))) -> 40 | L38: =IF(G38="",5,IF(G38>=2023,25,IF(G38>=2022,20,IF(G38>=2021,14,IF(G38>=2020,8,5))))) -> 8 | M38: =IFERROR(INDEX(Methodology!$B$27:$B$36,MATCH(J38,Methodology!$A$27:$A$36,0)),12) -> 20 | N38: =IF(COUNTIF(Infrastructure!$A:$A,A38)>=4,15,IF(COUNTIF(Infrastructure!$A:$A,A38)>=2,10,IF(COUNTIF(Infrastructure!$A:$A,A38)>=1,5,0))) -> 15 | O38: =K38+L38+M38+N38 -> 83 | P38: =IF(O38>=70,"High",IF(O38>=50,"Medium","Watch")) -> High | Q38: Phase One National Data Center at Konza Completed | R38: https://techweez.com/2020/07/20/phase-one-national-data-center-konza-completed/ | S38: July 20, 2020
A39: Kenya | B39: Microsoft (with G42) | C39: Technology | D39: Redmond, USA (partner G42 HQ'd in Abu Dhabi, UAE) | E39: Establishing Kenya as its flagship East African digital hub, including a new Azure cloud region and an Innovation Lab in Nairobi. | F39: Announced (with G42) a $1 billion comprehensive digital ecosystem initiative on May 22, 2024, including a geothermal-powered data centre in Olkaria and a new Azure East Africa Cloud Region. | G39: 2024 | H39: $1 billion | I39: 1000 | J39: Data Centre | K39: =IF(I39="",12,IF(I39>=100,40,IF(I39>=20,32,IF(I39>=5,24,IF(I39>=1,16,8))))) -> 40 | L39: =IF(G39="",5,IF(G39>=2023,25,IF(G39>=2022,20,IF(G39>=2021,14,IF(G39>=2020,8,5))))) -> 25 | M39: =IFERROR(INDEX(Methodology!$B$27:$B$36,MATCH(J39,Methodology!$A$27:$A$36,0)),12) -> 20 | N39: =IF(COUNTIF(Infrastructure!$A:$A,A39)>=4,15,IF(COUNTIF(Infrastructure!$A:$A,A39)>=2,10,IF(COUNTIF(Infrastructure!$A:$A,A39)>=1,5,0))) -> 15 | O39: =K39+L39+M39+N39 -> 100 | P39: =IF(O39>=70,"High",IF(O39>=50,"Medium","Watch")) -> High | Q39: Microsoft and G42 announce $1 billion comprehensive digital ecosystem initiative for Kenya | R39: https://news.microsoft.com/source/2024/05/22/microsoft-and-g42-announce-1-billion-comprehensive-digital-ecosystem-initiative-for-kenya/ | S39: May 22, 2024
A40: Kenya | B40: China Road and Bridge Corporation (CRBC) | C40: Construction | D40: Beijing, China | E40: Long-time Kenyan infrastructure contractor (built the SGR railway); returning to major road projects after a Chinese-lending pause that began around 2019. | F40: Launched Phase One ($863 million) of a $1.5 billion Nairobi-Mau Summit highway upgrade with Kenya's NSSF as equity partner, announced November 28, 2025; construction due by end-2027, followed by a 28-year toll concession. | G40: 2025 | H40: $863 million (Phase One of the overall $1.5 billion project) | I40: 863 | J40: Construction Project | K40: =IF(I40="",12,IF(I40>=100,40,IF(I40>=20,32,IF(I40>=5,24,IF(I40>=1,16,8))))) -> 40 | L40: =IF(G40="",5,IF(G40>=2023,25,IF(G40>=2022,20,IF(G40>=2021,14,IF(G40>=2020,8,5))))) -> 25 | M40: =IFERROR(INDEX(Methodology!$B$27:$B$36,MATCH(J40,Methodology!$A$27:$A$36,0)),12) -> 16 | N40: =IF(COUNTIF(Infrastructure!$A:$A,A40)>=4,15,IF(COUNTIF(Infrastructure!$A:$A,A40)>=2,10,IF(COUNTIF(Infrastructure!$A:$A,A40)>=1,5,0))) -> 15 | O40: =K40+L40+M40+N40 -> 96 | P40: =IF(O40>=70,"High",IF(O40>=50,"Medium","Watch")) -> High | Q40: Kenya turns to China for $1.5 billion highway expansion | R40: https://www.cnbcafrica.com/2025/kenya-turns-to-china-for-1-5-billion-highway-expansion | S40: November 28, 2025
...

Sheet Infrastructure
A1: Project Profile | F1: Status | H1: Source
A2: Country | B2: Project Name | C2: Type | D2: Location | E2: Operator / Developer | F2: Status | G2: Scale / Capacity | H2: Source Title | I2: Source URL | J2: Source Date
A3: Burundi | B3: Port of Bujumbura Modernization (Lake Tanganyika Transport Corridor Development Project, Phase I) | C3: Port | D3: Bujumbura, Burundi | E3: Government of Burundi, financed by African Development Bank Group and European Union | F3: Construction commenced August 17, 2023, with a 24-month completion timeline; project rehabilitates port equipment, access roads and staff capacity to establish Bujumbura as a Lake Tanganyika regional trade hub. | G3: €79 million total (€23.4M AfDB, €29M EU, €2M Government of Burundi) | H3: Burundi: the Port of Bujumbura will soon be renovated and modernized thanks to funding from the African Development Bank Group and the European Union | I3: https://www.afdb.org/en/news-and-events/press-releases/burundi-port-bujumbura-will-soon-be-renovated-and-modernized-thanks-funding-african-development-bank-group-and-european-union-63941 | J3: 2023-08-25
A4: Comoros | B4: Maritime Corridor and Regional Trade Facilitation Project | C4: Port | D4: Moroni, Mutsamudu and Mohéli, Comoros | E4: Government of the Union of the Comoros, financed by the African Development Bank Group and co-financiers | F4: Officially launched October 27, 2025, in Moroni (press release October 29, 2025); aims to modernize port infrastructure across the islands and position Comoros as an Africa-Asia logistics hub. | G4: $137 million total ($135M African Development Fund grant + $2M Transition Support Fund), with over $110M additional co-financing from the World Bank, Islamic Development Bank, AFD, EU and EIB | H4: Union of the Comoros: Launch of the maritime corridor project supported by the African Development Bank Group to the tune of $137 million | I4: https://www.afdb.org/en/news-and-events/press-releases/union-comoros-launch-maritime-corridor-project-supported-african-development-bank-group-tune-137-million-88185 | J4: 2025-10-29
A5: Comoros | B5: Port of Moroni Deep-Water Port Redevelopment | C5: Port | D5: Moroni, Grande Comore, Comoros | E5: China Road and Bridge Corporation (contracted); Government of Comoros | F5: Commercial contract signed March 2018 for dredging and redevelopment; as of the most recent available reporting (June 2022), construction work had reportedly not yet commenced. | G5: $165 million (contracted) | H5: Will Comoros Be China's Next "Djibouti" In Indian Ocean Region? | I5: https://channel16.dryadglobal.com/will-comoros-be-chinas-next-djibouti-in-indian-ocean-region | J5: 2022-06-10
A6: Djibouti | B6: Djibouti International Free Trade Zone (DIFTZ) | C6: SEZ | D6: Djibouti City, Djibouti | E6: Djibouti Ports & Free Zones Authority / Great Horn Investment Holding, with China Merchants Group | F6: Zone established 2015 (43.5 sq km) and operational since 2018; major expansion phase agreed January 8, 2021. | G6: 43.5 sq km; $3 billion expansion agreement (2021); $513 million initial phase (2020) | H6: China Merchants signs deal for $3bn expansion of Djibouti City port | I6: https://www.globalconstructionreview.com/china-merchants-signs-deal-3bn-expansion-djibouti/ | J6: 2021-01-08
