Workbook

Sheet Overview
A1: East & Southern Africa + UAE — Macroeconomic Indicators
A3: Source: World Bank Open Data (World Development Indicators), fetched September 2026. GDP (current US$): NY.GDP.MKTP.CD; GDP Growth (annual %): NY.GDP.MKTP.KD.ZG; GDP Per Capita (current US$): NY.GDP.PCAP.CD; Inflation, consumer prices (annual %): FP.CPI.TOTL.ZG; FDI, net inflows (% of GDP): BX.KLT.DINV.WD.GD.ZS.
A4: Coverage: 2019-2024, all 20 countries in your data model's DIM_COUNTRY — Kenya, Tanzania, Uganda, Rwanda, Ethiopia, UAE, plus the 14-country expansion (Burundi, Comoros, Djibouti, DRC Congo, Eritrea, Madagascar, Malawi, Mauritius, Mozambique, Seychelles, Somalia, South Sudan, Zambia, Zimbabwe).
A5: This is FACT_MACRO: it fills the GDP / GDP Growth / GDP Per Capita / Inflation / FDI columns of your data model for every country. Unlike the Company/Infrastructure and Regional Economy workbooks (compiled from individual sources), this one comes from a single official, programmatically-fetched dataset.
A7: How this workbook is organized
A8: Sheet | B8: Contents
A9: Data | B9: One row per Country x Year (20 countries x 2019-2024 = 120 rows), all 5 indicators.
A10: Country Snapshot | B10: One row per country showing the latest available (2024, or most recent non-blank) value for each indicator, for a fast cross-country comparison.
A12: Data notes
A13: • Blank cells mean the World Bank has not published that indicator/year for that country (not zero) — most commonly Eritrea and South Sudan, where data reporting is limited or interrupted, and occasional single-year gaps elsewhere (e.g. DRC Congo, Somalia and Zimbabwe inflation, Zimbabwe 2023-2024 inflation following its 2024 currency reform).
A14: • FDI is shown as net inflows as a % of GDP (not an absolute dollar figure) so it is comparable across economies of very different sizes — Mozambique's large LNG-linked FDI share and Seychelles' small, high-turnover economy both show up clearly this way.
A15: • All figures are as published by the World Bank at the time of fetching (September 2026) and are subject to the World Bank's own periodic revisions.
A16: • On the Country Snapshot sheet, "Latest Year (GDP)" reflects GDP's own most recent published year; each other indicator independently pulls its own latest available year, so two columns in the same row can reference different years where an indicator is reported on a lag (or missing) relative to GDP.

Sheet Data
C1: GDP | D1: Growth & Per Capita | F1: Prices | G1: Investment
A2: Country | B2: Year | C2: GDP (current US$) | D2: GDP Growth (%, annual) | E2: GDP Per Capita (current US$) | F2: Inflation, Consumer Prices (%, annual) | G2: FDI, Net Inflows (% of GDP)
A3: Kenya | B3: 2019 | C3: 1.0037844e+11 | D3: 5.1141589 | E3: 1960.4081 | F3: 5.239638 | G3: 0.46816855
A4: Kenya | B4: 2020 | C4: 1.0065751e+11 | D4: -0.27276633 | E4: 1927.6646 | F4: 5.4051621 | G4: -0.0053684544
A5: Kenya | B5: 2021 | C5: 1.0970366e+11 | D5: 7.5904895 | E5: 2061.3562 | F5: 6.107936 | G5: 0.382594
A6: Kenya | B6: 2022 | C6: 1.1444898e+11 | D6: 4.859981 | E6: 2109.5629 | F6: 7.6598627 | G6: 0.69164598
A7: Kenya | B7: 2023 | C7: 1.0750088e+11 | D7: 5.7199924 | E7: 1942.588 | F7: 7.6713963 | G7: 0.47252124
A8: Kenya | B8: 2024 | C8: 1.2039754e+11 | D8: 4.6601959 | E8: 2133.4619 | F8: 4.4897885 | G8: 0.38492457
A9: Tanzania | B9: 2019 | C9: 6.1026732e+10 | D9: 5.8 | E9: 1063.3225 | F9: 3.4642806 | G9: 1.9945935
A10: Tanzania | B10: 2020 | C10: 6.6068738e+10 | D10: 1.9919646 | E10: 1117.4153 | F10: 3.2902906 | G10: 1.4284597
A11: Tanzania | B11: 2021 | C11: 7.0655628e+10 | D11: 4.3213843 | E11: 1159.8566 | F11: 3.6909196 | G11: 1.6849435
A12: Tanzania | B12: 2022 | C12: 7.5749122e+10 | D12: 4.5660058 | E12: 1207.5206 | F12: 4.350272 | G12: 1.897811
A13: Tanzania | B13: 2023 | C13: 7.9030936e+10 | D13: 5.0695235 | E13: 1224.0022 | F13: 3.7992329 | G13: 2.0864157
A14: Tanzania | B14: 2024 | C14: 7.9235713e+10 | D14: 5.5263138 | E14: 1192.6067 | F14: 3.0569468 | G14: 2.1676781
... A56: Djibouti | B56: 2024 | C56: 4.1521459e+09 | D56: 6.9804847 | E56: 3552.7234 | F56: 2.1120117 | G56: 1.633371
A57: DRC Congo | B57: 2019 | C57: 4.68459e+10 | D57: 0.55538429 | E57: 504.00419 | G57: 2.8839113
A58: DRC Congo | B58: 2020 | C58: 4.669199e+10 | D58: 0.77542799 | E58: 486.42557 | G58: 3.2084407
A59: DRC Congo | B59: 2021 | C59: 5.906729e+10 | D59: 6.4296101 | E59: 595.74307 | G59: 2.8402756
A60: DRC Congo | B60: 2022 | C60: 7.0422346e+10 | D60: 9.3111694 | E60: 687.73859 | G60: 2.0013162
A61: DRC Congo | B61: 2023 | C61: 6.9843655e+10 | D61: 8.5334898 | E61: 660.21205 | G61: 3.4008227
A62: DRC Congo | B62: 2024 | C62: 7.5716176e+10 | D62: 6.1025294 | E62: 692.88767 | G62: 3.8499769
A63: Eritrea | B63: 2019
A64: Eritrea | B64: 2020
A65: Eritrea | B65: 2021
A66: Eritrea | B66: 2022
A67: Eritrea | B67: 2023
A68: Eritrea | B68: 2024
A69: Madagascar | B69: 2019 | C69: 1.4104665e+10 | D69: 4.4112321 | E69: 499.81884 | F69: 5.6105144 | G69: 3.3627983
A70: Madagascar | B70: 2020 | C70: 1.3051441e+10 | D70: -7.1376716 | E70: 450.77162 | F70: 4.2017931 | G70: 2.7465713
A71: Madagascar | B71: 2021 | C71: 1.4354732e+10 | D71: 4.6506834 | E71: 483.46946 | F71: 5.8122512 | G71: 2.4907234
A72: Madagascar | B72: 2022 | C72: 1.5342179e+10 | D72: 4.1375353 | E72: 504.05911 | F72: 8.1605903 | G72: 3.0494278
A73: Madagascar | B73: 2023 | C73: 1.6036708e+10 | D73: 4.2308658 | E73: 514.06408 | F73: 9.8743268 | G73: 3.2395379
A74: Madagascar | B74: 2024 | C74: 1.7592833e+10 | D74: 4.3228373 | E74: 550.37876 | F74: 7.6133578 | G74: 3.4457711
A75: Malawi | B75: 2019 | C75: 1.1051853e+10 | D75: 5.7168252 | E75: 580.88914 | F75: 9.3708361 | G75: 0.4997156
A76: Malawi | B76: 2020 | C76: 1.1769314e+10 | D76: 0.79359643 | E76: 602.50748 | F76: 8.6255147 | G76: 2.1426826
A77: Malawi | B77: 2021 | C77: 1.2378119e+10 | D77: 4.5582921 | E77: 617.44699 | F77: 9.3301441 | G77: 1.0461774
A78: Malawi | B78: 2022 | C78: 1.242906e+10 | D78: 0.92111507 | E78: 604.26974 | F78: 20.95397 | G78: 1.5988862
A79: Malawi | B79: 2023 | C79: 1.336367e+10 | D79: 1.9457528 | E79: 633.21477 | F79: 28.789743 | G79: 1.6010611
A80: Malawi | B80: 2024 | C80: 1.1311971e+10 | D80: 1.6734341 | E80: 522.36537 | F80: 32.17965 | G80: 2.2805308
... A98: Seychelles | B98: 2024 | C98: 2.2286087e+09 | D98: 3.3466743 | E98: 18364.526 | F98: 0.31172605 | G98: 10.146874
...

Sheet Country Snapshot
C1: GDP | D1: Growth & Per Capita | F1: Prices | G1: Investment
A2: Country | B2: Latest Year (GDP) | C2: GDP (current US$) | D2: GDP Growth (%, annual) | E2: GDP Per Capita (current US$) | F2: Inflation, Consumer Prices (%, annual) | G2: FDI, Net Inflows (% of GDP)
A3: Kenya | B3: 2024 | C3: =IFERROR(SUMIFS(Data!$C$3:$C$122,Data!$A$3:$A$122,A3,Data!$B$3:$B$122,2024),"n/a") -> 1.2039754e+11 | D3: =IFERROR(SUMIFS(Data!$D$3:$D$122,Data!$A$3:$A$122,A3,Data!$B$3:$B$122,2024),"n/a") -> 4.6601959 | E3: =IFERROR(SUMIFS(Data!$E$3:$E$122,Data!$A$3:$A$122,A3,Data!$B$3:$B$122,2024),"n/a") -> 2133.4619 | F3: =IFERROR(SUMIFS(Data!$F$3:$F$122,Data!$A$3:$A$122,A3,Data!$B$3:$B$122,2024),"n/a") -> 4.4897885 | G3: =IFERROR(SUMIFS(Data!$G$3:$G$122,Data!$A$3:$A$122,A3,Data!$B$3:$B$122,2024),"n/a") -> 0.38492457
A4: Tanzania | B4: 2024 | C4: =IFERROR(SUMIFS(Data!$C$3:$C$122,Data!$A$3:$A$122,A4,Data!$B$3:$B$122,2024),"n/a") -> 7.9235713e+10 | D4: =IFERROR(SUMIFS(Data!$D$3:$D$122,Data!$A$3:$A$122,A4,Data!$B$3:$B$122,2024),"n/a") -> 5.5263138 | E4: =IFERROR(SUMIFS(Data!$E$3:$E$122,Data!$A$3:$A$122,A4,Data!$B$3:$B$122,2024),"n/a") -> 1192.6067 | F4: =IFERROR(SUMIFS(Data!$F$3:$F$122,Data!$A$3:$A$122,A4,Data!$B$3:$B$122,2024),"n/a") -> 3.0569468 | G4: =IFERROR(SUMIFS(Data!$G$3:$G$122,Data!$A$3:$A$122,A4,Data!$B$3:$B$122,2024),"n/a") -> 2.1676781
A5: Uganda | B5: 2024 | C5: =IFERROR(SUMIFS(Data!$C$3:$C$122,Data!$A$3:$A$122,A5,Data!$B$3:$B$122,2024),"n/a") -> 5.3911907e+10 | D5: =IFERROR(SUMIFS(Data!$D$3:$D$122,Data!$A$3:$A$122,A5,Data!$B$3:$B$122,2024),"n/a") -> 6.0555808 | E5: =IFERROR(SUMIFS(Data!$E$3:$E$122,Data!$A$3:$A$122,A5,Data!$B$3:$B$122,2024),"n/a") -> 1077.9128 | F5: =IFERROR(SUMIFS(Data!$F$3:$F$122,Data!$A$3:$A$122,A5,Data!$B$3:$B$122,2024),"n/a") -> 3.3233803 | G5: =IFERROR(SUMIFS(Data!$G$3:$G$122,Data!$A$3:$A$122,A5,Data!$B$3:$B$122,2024),"n/a") -> 6.0417047
A6: Rwanda | B6: 2024 | C6: =IFERROR(SUMIFS(Data!$C$3:$C$122,Data!$A$3:$A$122,A6,Data!$B$3:$B$122,2024),"n/a") -> 1.5111064e+10 | D6: =IFERROR(SUMIFS(Data!$D$3:$D$122,Data!$A$3:$A$122,A6,Data!$B$3:$B$122,2024),"n/a") -> 7.227171 | E6: =IFERROR(SUMIFS(Data!$E$3:$E$122,Data!$A$3:$A$122,A6,Data!$B$3:$B$122,2024),"n/a") -> 1059.9371 | F6: =IFERROR(SUMIFS(Data!$F$3:$F$122,Data!$A$3:$A$122,A6,Data!$B$3:$B$122,2024),"n/a") -> 1.7702924 | G6: =IFERROR(SUMIFS(Data!$G$3:$G$122,Data!$A$3:$A$122,A6,Data!$B$3:$B$122,2024),"n/a") -> 3.7914557
A7: Ethiopia | B7: 2024 | C7: =IFERROR(SUMIFS(Data!$C$3:$C$122,Data!$A$3:$A$122,A7,Data!$B$3:$B$122,2024),"n/a") -> 1.497403e+11 | D7: =IFERROR(SUMIFS(Data!$D$3:$D$122,Data!$A$3:$A$122,A7,Data!$B$3:$B$122,2024),"n/a") -> 7.6127745 | E7: =IFERROR(SUMIFS(Data!$E$3:$E$122,Data!$A$3:$A$122,A7,Data!$B$3:$B$122,2024),"n/a") -> 1133.8828 | F7: =IFERROR(SUMIFS(Data!$F$3:$F$122,Data!$A$3:$A$122,A7,Data!$B$3:$B$122,2024),"n/a") -> 21.037746 | G7: =IFERROR(SUMIFS(Data!$G$3:$G$122,Data!$A$3:$A$122,A7,Data!$B$3:$B$122,2024),"n/a") -> 2.6858203
A8: United Arab Emirates | B8: 2024 | C8: =IFERROR(SUMIFS(Data!$C$3:$C$122,Data!$A$3:$A$122,A8,Data!$B$3:$B$122,2024),"n/a") -> 5.5232492e+11 | D8: =IFERROR(SUMIFS(Data!$D$3:$D$122,Data!$A$3:$A$122,A8,Data!$B$3:$B$122,2024),"n/a") -> 3.991812 | E8: =IFERROR(SUMIFS(Data!$E$3:$E$122,Data!$A$3:$A$122,A8,Data!$B$3:$B$122,2024),"n/a") -> 50273.513 | F8: =IFERROR(SUMIFS(Data!$F$3:$F$122,Data!$A$3:$A$122,A8,Data!$B$3:$B$122,2024),"n/a") -> 1.6633651 | G8: =IFERROR(SUMIFS(Data!$G$3:$G$122,Data!$A$3:$A$122,A8,Data!$B$3:$B$122,2024),"n/a") -> 8.262616
A9: Burundi | B9: 2024 | C9: =IFERROR(SUMIFS(Data!$C$3:$C$122,Data!$A$3:$A$122,A9,Data!$B$3:$B$122,2024),"n/a") -> 3.0375799e+09 | D9: =IFERROR(SUMIFS(Data!$D$3:$D$122,Data!$A$3:$A$122,A9,Data!$B$3:$B$122,2024),"n/a") -> 4.1122738 | E9: =IFERROR(SUMIFS(Data!$E$3:$E$122,Data!$A$3:$A$122,A9,Data!$B$3:$B$122,2024),"n/a") -> 216.23193 | F9: =IFERROR(SUMIFS(Data!$F$3:$F$122,Data!$A$3:$A$122,A9,Data!$B$3:$B$122,2024),"n/a") -> 20.212493 | G9: =IFERROR(SUMIFS(Data!$G$3:$G$122,Data!$A$3:$A$122,A9,Data!$B$3:$B$122,2024),"n/a") -> 1.0970223
A10: Comoros | B10: 2024 | C10: =IFERROR(SUMIFS(Data!$C$3:$C$122,Data!$A$3:$A$122,A10,Data!$B$3:$B$122,2024),"n/a") -> 1.6100827e+09 | D10: =IFERROR(SUMIFS(Data!$D$3:$D$122,Data!$A$3:$A$122,A10,Data!$B$3:$B$122,2024),"n/a") -> 3.300715 | E10: =IFERROR(SUMIFS(Data!$E$3:$E$122,Data!$A$3:$A$122,A10,Data!$B$3:$B$122,2024),"n/a") -> 1857.8706 | F10: =IFERROR(SUMIFS(Data!$F$3:$F$122,Data!$A$3:$A$122,A10,Data!$B$3:$B$122,2024),"n/a") -> 5.0519261 | G10: =IFERROR(SUMIFS(Data!$G$3:$G$122,Data!$A$3:$A$122,A10,Data!$B$3:$B$122,2024),"n/a") -> 0.44097114
A11: Djibouti | B11: 2024 | C11: =IFERROR(SUMIFS(Data!$C$3:$C$122,Data!$A$3:$A$122,A11,Data!$B$3:$B$122,2024),"n/a") -> 4.1521459e+09 | D11: =IFERROR(SUMIFS(Data!$D$3:$D$122,Data!$A$3:$A$122,A11,Data!$B$3:$B$122,2024),"n/a") -> 6.9804847 | E11: =IFERROR(SUMIFS(Data!$E$3:$E$122,Data!$A$3:$A$122,A11,Data!$B$3:$B$122,2024),"n/a") -> 3552.7234 | F11: =IFERROR(SUMIFS(Data!$F$3:$F$122,Data!$A$3:$A$122,A11,Data!$B$3:$B$122,2024),"n/a") -> 2.1120117 | G11: =IFERROR(SUMIFS(Data!$G$3:$G$122,Data!$A$3:$A$122,A11,Data!$B$3:$B$122,2024),"n/a") -> 1.633371
A12: DRC Congo | B12: 2024 | C12: =IFERROR(SUMIFS(Data!$C$3:$C$122,Data!$A$3:$A$122,A12,Data!$B$3:$B$122,2024),"n/a") -> 7.5716176e+10 | D12: =IFERROR(SUMIFS(Data!$D$3:$D$122,Data!$A$3:$A$122,A12,Data!$B$3:$B$122,2024),"n/a") -> 6.1025294 | E12: =IFERROR(SUMIFS(Data!$E$3:$E$122,Data!$A$3:$A$122,A12,Data!$B$3:$B$122,2024),"n/a") -> 692.88767 | F12: n/a | G12: =IFERROR(SUMIFS(Data!$G$3:$G$122,Data!$A$3:$A$122,A12,Data!$B$3:$B$122,2024),"n/a") -> 3.8499769
A13: Eritrea | B13: n/a | C13: n/a | D13: n/a | E13: n/a | F13: n/a | G13: n/a
A14: Madagascar | B14: 2024 | C14: =IFERROR(SUMIFS(Data!$C$3:$C$122,Data!$A$3:$A$122,A14,Data!$B$3:$B$122,2024),"n/a") -> 1.7592833e+10 | D14: =IFERROR(SUMIFS(Data!$D$3:$D$122,Data!$A$3:$A$122,A14,Data!$B$3:$B$122,2024),"n/a") -> 4.3228373 | E14: =IFERROR(SUMIFS(Data!$E$3:$E$122,Data!$A$3:$A$122,A14,Data!$B$3:$B$122,2024),"n/a") -> 550.37876 | F14: =IFERROR(SUMIFS(Data!$F$3:$F$122,Data!$A$3:$A$122,A14,Data!$B$3:$B$122,2024),"n/a") -> 7.6133578 | G14: =IFERROR(SUMIFS(Data!$G$3:$G$122,Data!$A$3:$A$122,A14,Data!$B$3:$B$122,2024),"n/a") -> 3.4457711
A15: Malawi | B15: 2024 | C15: =IFERROR(SUMIFS(Data!$C$3:$C$122,Data!$A$3:$A$122,A15,Data!$B$3:$B$122,2024),"n/a") -> 1.1311971e+10 | D15: =IFERROR(SUMIFS(Data!$D$3:$D$122,Data!$A$3:$A$122,A15,Data!$B$3:$B$122,2024),"n/a") -> 1.6734341 | E15: =IFERROR(SUMIFS(Data!$E$3:$E$122,Data!$A$3:$A$122,A15,Data!$B$3:$B$122,2024),"n/a") -> 522.36537 | F15: =IFERROR(SUMIFS(Data!$F$3:$F$122,Data!$A$3:$A$122,A15,Data!$B$3:$B$122,2024),"n/a") -> 32.17965 | G15: =IFERROR(SUMIFS(Data!$G$3:$G$122,Data!$A$3:$A$122,A15,Data!$B$3:$B$122,2024),"n/a") -> 2.2805308
A16: Mauritius | B16: 2024 | C16: =IFERROR(SUMIFS(Data!$C$3:$C$122,Data!$A$3:$A$122,A16,Data!$B$3:$B$122,2024),"n/a") -> 1.4938056e+10 | D16: =IFERROR(SUMIFS(Data!$D$3:$D$122,Data!$A$3:$A$122,A16,Data!$B$3:$B$122,2024),"n/a") -> 4.9484424 | E16: =IFERROR(SUMIFS(Data!$E$3:$E$122,Data!$A$3:$A$122,A16,Data!$B$3:$B$122,2024),"n/a") -> 11990.936 | F16: =IFERROR(SUMIFS(Data!$F$3:$F$122,Data!$A$3:$A$122,A16,Data!$B$3:$B$122,2024),"n/a") -> 3.604522 | G16: =IFERROR(SUMIFS(Data!$G$3:$G$122,Data!$A$3:$A$122,A16,Data!$B$3:$B$122,2024),"n/a") -> 4.5606754
A17: Mozambique | B17: 2024 | C17: =IFERROR(SUMIFS(Data!$C$3:$C$122,Data!$A$3:$A$122,A17,Data!$B$3:$B$122,2024),"n/a") -> 2.2752244e+10 | D17: =IFERROR(SUMIFS(Data!$D$3:$D$122,Data!$A$3:$A$122,A17,Data!$B$3:$B$122,2024),"n/a") -> 2.148925 | E17: =IFERROR(SUMIFS(Data!$E$3:$E$122,Data!$A$3:$A$122,A17,Data!$B$3:$B$122,2024),"n/a") -> 656.97615 | F17: =IFERROR(SUMIFS(Data!$F$3:$F$122,Data!$A$3:$A$122,A17,Data!$B$3:$B$122,2024),"n/a") -> 4.0785683 | G17: =IFERROR(SUMIFS(Data!$G$3:$G$122,Data!$A$3:$A$122,A17,Data!$B$3:$B$122,2024),"n/a") -> 15.421012
A18: Seychelles | B18: 2024 | C18: =IFERROR(SUMIFS(Data!$C$3:$C$122,Data!$A$3:$A$122,A18,Data!$B$3:$B$122,2024),"n/a") -> 2.2286087e+09 | D18: =IFERROR(SUMIFS(Data!$D$3:$D$122,Data!$A$3:$A$122,A18,Data!$B$3:$B$122,2024),"n/a") -> 3.3466743 | E18: =IFERROR(SUMIFS(Data!$E$3:$E$122,Data!$A$3:$A$122,A18,Data!$B$3:$B$122,2024),"n/a") -> 18364.526 | F18: =IFERROR(SUMIFS(Data!$F$3:$F$122,Data!$A$3:$A$122,A18,Data!$B$3:$B$122,2024),"n/a") -> 0.31172605 | G18: =IFERROR(SUMIFS(Data!$G$3:$G$122,Data!$A$3:$A$122,A18,Data!$B$3:$B$122,2024),"n/a") -> 10.146874
A19: Somalia | B19: 2024 | C19: =IFERROR(SUMIFS(Data!$C$3:$C$122,Data!$A$3:$A$122,A19,Data!$B$3:$B$122,2024),"n/a") -> 11967000000 | D19: =IFERROR(SUMIFS(Data!$D$3:$D$122,Data!$A$3:$A$122,A19,Data!$B$3:$B$122,2024),"n/a") -> 4.1113934 | E19: =IFERROR(SUMIFS(Data!$E$3:$E$122,Data!$A$3:$A$122,A19,Data!$B$3:$B$122,2024),"n/a") -> 629.5389 | F19: n/a | G19: =IFERROR(SUMIFS(Data!$G$3:$G$122,Data!$A$3:$A$122,A19,Data!$B$3:$B$122,2024),"n/a") -> 6.3925796
A20: South Sudan | B20: n/a | C20: n/a | D20: n/a | E20: n/a | F20: =IFERROR(SUMIFS(Data!$F$3:$F$122,Data!$A$3:$A$122,A20,Data!$B$3:$B$122,2024),"n/a") -> 91.440822 | G20: n/a
A21: Zambia | B21: 2024 | C21: =IFERROR(SUMIFS(Data!$C$3:$C$122,Data!$A$3:$A$122,A21,Data!$B$3:$B$122,2024),"n/a") -> 2.5303185e+10 | D21: =IFERROR(SUMIFS(Data!$D$3:$D$122,Data!$A$3:$A$122,A21,Data!$B$3:$B$122,2024),"n/a") -> 3.8200483 | E21: =IFERROR(SUMIFS(Data!$E$3:$E$122,Data!$A$3:$A$122,A21,Data!$B$3:$B$122,2024),"n/a") -> 1187.1094 | F21: =IFERROR(SUMIFS(Data!$F$3:$F$122,Data!$A$3:$A$122,A21,Data!$B$3:$B$122,2024),"n/a") -> 14.985626 | G21: =IFERROR(SUMIFS(Data!$G$3:$G$122,Data!$A$3:$A$122,A21,Data!$B$3:$B$122,2024),"n/a") -> 9.3243779
A22: Zimbabwe | B22: 2024 | C22: =IFERROR(SUMIFS(Data!$C$3:$C$122,Data!$A$3:$A$122,A22,Data!$B$3:$B$122,2024),"n/a") -> 4.1521976e+10 | D22: =IFERROR(SUMIFS(Data!$D$3:$D$122,Data!$A$3:$A$122,A22,Data!$B$3:$B$122,2024),"n/a") -> 1.6764945 | E22: =IFERROR(SUMIFS(Data!$E$3:$E$122,Data!$A$3:$A$122,A22,Data!$B$3:$B$122,2024),"n/a") -> 2496.1551 | F22: =IFERROR(SUMIFS(Data!$F$3:$F$122,Data!$A$3:$A$122,A22,Data!$B$3:$B$122,2022),"n/a") -> 104.70517 | G22: =IFERROR(SUMIFS(Data!$G$3:$G$122,Data!$A$3:$A$122,A22,Data!$B$3:$B$122,2024),"n/a") -> 1.1209317
