Workbook

Sheet Overview
A1: East African Countries — Social & Demographic Indicators
A3: Restructured from the original UIS Data Browser export you shared, using the WITS Kenya product workbook's flat-table layout as the structural guide.
A5: How this workbook is organized
A6: This file replaces the original page-by-page (A, B, C ...) layout with a single structured dataset, modeled on the flat, one-row-per-record layout used in the WITS Kenya product-trade workbook you shared: identifier columns (Country, Year) on the left, every measure as its own column to the right, grouped and color-coded by theme instead of split into separate lettered pages.
A10: Sheet | B10: Contents
A11: Data | B11: One row per country/year, with every indicator as its own column, grouped and color-banded by theme.
A12: Latest Snapshot | B12: One row per country with each indicator's most recently available value, pulled live from the Data sheet with formulas.
A14: Theme groupings
A15: Theme | B15: Indicators included
A16: Fertility & Reproductive Health | B16: Fertility rate, total (births per woman)
A17: Mortality & Life Expectancy | B17: Life expectancy at birth, total (years); Mortality rate, infant (per 1,000 live births); Prevalence of HIV, total (% of population ages 15-49)
A18: Population Growth & Age Structure | B18: Population growth (annual %); Population aged 15-24 years (thousands); Population aged 25-64 years (thousands); Population aged 65 years or older (thousands)
A19: Urbanization & Settlement | B19: Rural population (% of total population)
A21: Data notes (carried over from the original source files)
A22: • Source: UIS Data Browser (databrowser.uis.unesco.org).
A23: • Most indicators cover 2020-2023. Population growth and HIV prevalence extend through 2024; all other indicators have no 2024 figures in the source, so those cells are blank for 2024 rather than zero.
A24: • Mauritius and Seychelles have no HIV prevalence data in the source view.
A25: • Population aged 25-64 (thousands): Rwanda through Zimbabwe (8 countries) could not be transcribed from the original source screenshots (a duplicated page image) and are blank here pending the original data.
A26: • Population growth for Seychelles is blank for 2022 in the source (data gap, not zero).
A27: • Somalia's infant mortality rate shows an unusual spike to 89.90 in 2022 versus 71.80 (2021) and 67.80 (2023); transcribed exactly as it appeared in the source.
A28: • All blank cells reflect no data available in the original source, not a value of zero.

Sheet Data
A1: Country | B1: Year | C1: Fertility & Reproductive Health | D1: Mortality & Life Expectancy | G1: Population Growth & Age Structure | K1: Urbanization & Settlement
C2: Fertility rate, total (births per woman) | D2: Life expectancy at birth, total (years) | E2: Mortality rate, infant (per 1,000 live births) | F2: Prevalence of HIV, total (% of population ages 15-49) | G2: Population growth (annual %) | H2: Population aged 15-24 years (thousands) | I2: Population aged 25-64 years (thousands) | J2: Population aged 65 years or older (thousands) | K2: Rural population (% of total population)
A3: Burundi | B3: 2020 | C3: 5.18 | D3: 62.57 | E3: 34.5 | F3: 1 | G3: 2.91 | H3: 2232.45 | I3: 4040.14 | J3: 301.06 | K3: 86.29
A4: Burundi | B4: 2021 | C4: 5.08 | D4: 62.1 | E4: 33.4 | F4: 0.9 | G4: 2.72 | H4: 2330.73 | I4: 4167.19 | J4: 313.41 | K4: 85.94
A5: Burundi | B5: 2022 | C5: 4.98 | D5: 62.88 | E5: 32.4 | F5: 0.9 | G5: 2.71 | H5: 2442.3 | I5: 4289.5 | J5: 324.98 | K5: 85.58
A6: Burundi | B6: 2023 | C6: 4.88 | D6: 63.65 | E6: 31.5 | F6: 0.8 | G6: 2.73 | H6: 2580.83 | I6: 4414.82 | J6: 337.31 | K6: 85.22
A7: Burundi | B7: 2024 | F7: 0.8 | G7: 2.58
A8: Comoros | B8: 2020 | C8: 4.07 | D8: 65.76 | E8: 38.7 | F8: 0.1 | G8: 1.96 | H8: 151.91 | I8: 301.72 | J8: 35.51 | K8: 70.62
A9: Comoros | B9: 2021 | C9: 4 | D9: 65.2 | E9: 37.8 | F9: 0.1 | G9: 1.98 | H9: 155.72 | I9: 309.36 | J9: 36.17 | K9: 70.39
A10: Comoros | B10: 2022 | C10: 3.94 | D10: 66.48 | E10: 36.8 | F10: 0.1 | G10: 1.94 | H10: 159.21 | I10: 317.27 | J10: 36.74 | K10: 70.14
A11: Comoros | B11: 2023 | C11: 3.88 | D11: 66.78 | E11: 35.7 | F11: 0.1 | G11: 1.92 | H11: 162.11 | I11: 326.17 | J11: 37.59 | K11: 69.87
A12: Comoros | B12: 2024 | F12: 0.1 | G12: 1.89
A13: Democratic Republic of the Congo | B13: 2020 | C13: 6.21 | D13: 60.43 | E13: 48.4 | F13: 0.9 | G13: 3.22 | H13: 18144.66 | I13: 29888.65 | J13: 2919.4 | K13: 54.36
A14: Democratic Republic of the Congo | B14: 2021 | C14: 6.16 | D14: 60.04 | E14: 47.1 | F14: 0.8 | G14: 3.24 | H14: 18641.27 | I14: 30969 | J14: 3005.25 | K14: 53.77
A15: Democratic Republic of the Congo | B15: 2022 | C15: 6.11 | D15: 60.98 | E15: 45.8 | F15: 0.8 | G15: 3.22 | H15: 19178.63 | I15: 32010 | J15: 3089.69 | K15: 53.16
A16: Democratic Republic of the Congo | B16: 2023 | C16: 6.05 | D16: 61.9 | E16: 44.5 | F16: 0.8 | G16: 3.26 | H16: 19806.45 | I16: 33084.97 | J16: 3189.39 | K16: 52.56
A17: Democratic Republic of the Congo | B17: 2024 | F17: 0.7 | G17: 3.24
A18: Djibouti | B18: 2020 | C18: 2.75 | D18: 64.2 | E18: 48.8 | F18: 1.2 | G18: 1.5 | H18: 217.88 | I18: 487.26 | J18: 48.74 | K18: 21.94
A19: Djibouti | B19: 2021 | C19: 2.7 | D19: 63.83 | E19: 47.3 | F19: 1.1 | G19: 1.44 | H19: 221.23 | I19: 499.68 | J19: 50.17 | K19: 21.78
A20: Djibouti | B20: 2022 | C20: 2.65 | D20: 65.54 | E20: 45.9 | F20: 1 | G20: 1.4 | H20: 224.21 | I20: 511.63 | J20: 51.66 | K20: 21.62
A21: Djibouti | B21: 2023 | C21: 2.61 | D21: 65.99 | E21: 44.4 | F21: 1 | G21: 1.38 | H21: 226.7 | I21: 523.63 | J21: 53.57 | K21: 21.45
A22: Djibouti | B22: 2024 | F22: 0.9 | G22: 1.36
A23: Eritrea | B23: 2020 | C23: 3.93 | D23: 66.98 | E23: 27.9 | F23: 0.5 | G23: 1.56 | H23: 705.01 | I23: 1095.26 | J23: 133.27 | K23: 58.65
A24: Eritrea | B24: 2021 | C24: 3.87 | D24: 66.94 | E24: 27.2 | F24: 0.5 | G24: 1.77 | H24: 729.35 | I24: 1124.1 | J24: 136.02 | K24: 58.02
A25: Eritrea | B25: 2022 | C25: 3.79 | D25: 67.79 | E25: 26.4 | F25: 0.5 | G25: 1.75 | H25: 745.3 | I25: 1161.87 | J25: 138.74 | K25: 57.38
A26: Eritrea | B26: 2023 | C26: 3.71 | D26: 68.62 | E26: 25.5 | F26: 0.4 | G26: 1.77 | H26: 760.38 | I26: 1197.6 | J26: 141.93 | K26: 56.73
A27: Eritrea | B27: 2024 | F27: 0.4 | G27: 1.86
A28: Ethiopia | B28: 2020 | C28: 4.27 | D28: 65.97 | E28: 39.6 | F28: 0.9 | G28: 2.71 | H28: 25142.62 | I28: 40880.78 | J28: 3583.33 | K28: 78.31
A29: Ethiopia | B29: 2021 | C29: 4.18 | D29: 65.33 | E29: 38.3 | F29: 0.8 | G29: 2.67 | H29: 25791.61 | I29: 42514.86 | J29: 3715.95 | K29: 77.83
A30: Ethiopia | B30: 2022 | C30: 4.08 | D30: 66.9 | E30: 37 | F30: 0.8 | G30: 2.62 | H30: 26391.45 | I30: 44153.11 | J30: 3841.03 | K30: 77.34
A31: Ethiopia | B31: 2023 | C31: 3.99 | D31: 67.31 | E31: 35.7 | F31: 0.7 | G31: 2.6 | H31: 26961.07 | I31: 45858.2 | J31: 3994.02 | K31: 76.84
A32: Ethiopia | B32: 2024 | F32: 0.7 | G32: 2.58
A33: Kenya | B33: 2020 | C33: 3.36 | D33: 61.6 | E33: 36.9 | F33: 3.7 | G33: 1.96 | H33: 10584.49 | I33: 19218.93 | J33: 1439.11 | K33: 72
A34: Kenya | B34: 2021 | C34: 3.31 | D34: 61.23 | E34: 36.4 | F34: 3.6 | G34: 1.9 | H34: 10905.6 | I34: 19786.44 | J34: 1473.81 | K34: 71.51
A35: Kenya | B35: 2022 | C35: 3.26 | D35: 63.55 | E35: 35.8 | F35: 3.4 | G35: 1.92 | H35: 11221.39 | I35: 20346.53 | J35: 1526.27 | K35: 71
A36: Kenya | B36: 2023 | C36: 3.21 | D36: 63.65 | E36: 34.7 | F36: 3.2 | G36: 1.98 | H36: 11568.02 | I36: 20952.31 | J36: 1581.23 | K36: 70.48
A37: Kenya | B37: 2024 | F37: 3 | G37: 1.96
A38: Madagascar | B38: 2020 | C38: 4.17 | D38: 62.71 | E38: 44.7 | F38: 0.3 | G38: 2.57 | H38: 5902.84 | I38: 10206.8 | J38: 894.12 | K38: 61.47
A39: Madagascar | B39: 2021 | C39: 4.1 | D39: 62.52 | E39: 44.9 | F39: 0.4 | G39: 2.52 | H39: 6031.09 | I39: 10552.06 | J39: 932.02 | K39: 60.79
A40: Madagascar | B40: 2022 | C40: 4.04 | D40: 63.07 | E40: 44.7 | F40: 0.4 | G40: 2.48 | H40: 6151.93 | I40: 10909.56 | J40: 972.55 | K40: 60.12
...

Sheet 2023 Latest Snapshot
A1: Country | B1: Fertility & Reproductive Health | C1: Mortality & Life Expectancy | F1: Population Growth & Age Structure | J1: Urbanization & Settlement
B2: Fertility rate, total (births per woman) | C2: Life expectancy at birth, total (years) | D2: Mortality rate, infant (per 1,000 live births) | E2: Prevalence of HIV, total (% of population ages 15-49) | F2: Population growth (annual %) | G2: Population aged 15-24 years (thousands) | H2: Population aged 25-64 years (thousands) | I2: Population aged 65 years or older (thousands) | J2: Rural population (% of total population)
A3: Burundi | B3: =IFERROR(SUMIFS(Data!C$3:C$97,Data!$A$3:$A$97,$A3,Data!$B$3:$B$97,2023),"n/a") -> 4.88 | C3: =IFERROR(SUMIFS(Data!D$3:D$97,Data!$A$3:$A$97,$A3,Data!$B$3:$B$97,2023),"n/a") -> 63.65 | D3: =IFERROR(SUMIFS(Data!E$3:E$97,Data!$A$3:$A$97,$A3,Data!$B$3:$B$97,2023),"n/a") -> 31.5 | E3: =IFERROR(SUMIFS(Data!F$3:F$97,Data!$A$3:$A$97,$A3,Data!$B$3:$B$97,2024),"n/a") -> 0.8 | F3: =IFERROR(SUMIFS(Data!G$3:G$97,Data!$A$3:$A$97,$A3,Data!$B$3:$B$97,2024),"n/a") -> 2.58 | G3: =IFERROR(SUMIFS(Data!H$3:H$97,Data!$A$3:$A$97,$A3,Data!$B$3:$B$97,2023),"n/a") -> 2580.83 | H3: =IFERROR(SUMIFS(Data!I$3:I$97,Data!$A$3:$A$97,$A3,Data!$B$3:$B$97,2023),"n/a") -> 4414.82 | I3: =IFERROR(SUMIFS(Data!J$3:J$97,Data!$A$3:$A$97,$A3,Data!$B$3:$B$97,2023),"n/a") -> 337.31 | J3: =IFERROR(SUMIFS(Data!K$3:K$97,Data!$A$3:$A$97,$A3,Data!$B$3:$B$97,2023),"n/a") -> 85.22
A4: Comoros | B4: =IFERROR(SUMIFS(Data!C$3:C$97,Data!$A$3:$A$97,$A4,Data!$B$3:$B$97,2023),"n/a") -> 3.88 | C4: =IFERROR(SUMIFS(Data!D$3:D$97,Data!$A$3:$A$97,$A4,Data!$B$3:$B$97,2023),"n/a") -> 66.78 | D4: =IFERROR(SUMIFS(Data!E$3:E$97,Data!$A$3:$A$97,$A4,Data!$B$3:$B$97,2023),"n/a") -> 35.7 | E4: =IFERROR(SUMIFS(Data!F$3:F$97,Data!$A$3:$A$97,$A4,Data!$B$3:$B$97,2024),"n/a") -> 0.1 | F4: =IFERROR(SUMIFS(Data!G$3:G$97,Data!$A$3:$A$97,$A4,Data!$B$3:$B$97,2024),"n/a") -> 1.89 | G4: =IFERROR(SUMIFS(Data!H$3:H$97,Data!$A$3:$A$97,$A4,Data!$B$3:$B$97,2023),"n/a") -> 162.11 | H4: =IFERROR(SUMIFS(Data!I$3:I$97,Data!$A$3:$A$97,$A4,Data!$B$3:$B$97,2023),"n/a") -> 326.17 | I4: =IFERROR(SUMIFS(Data!J$3:J$97,Data!$A$3:$A$97,$A4,Data!$B$3:$B$97,2023),"n/a") -> 37.59 | J4: =IFERROR(SUMIFS(Data!K$3:K$97,Data!$A$3:$A$97,$A4,Data!$B$3:$B$97,2023),"n/a") -> 69.87
A5: Democratic Republic of the Congo | B5: =IFERROR(SUMIFS(Data!C$3:C$97,Data!$A$3:$A$97,$A5,Data!$B$3:$B$97,2023),"n/a") -> 6.05 | C5: =IFERROR(SUMIFS(Data!D$3:D$97,Data!$A$3:$A$97,$A5,Data!$B$3:$B$97,2023),"n/a") -> 61.9 | D5: =IFERROR(SUMIFS(Data!E$3:E$97,Data!$A$3:$A$97,$A5,Data!$B$3:$B$97,2023),"n/a") -> 44.5 | E5: =IFERROR(SUMIFS(Data!F$3:F$97,Data!$A$3:$A$97,$A5,Data!$B$3:$B$97,2024),"n/a") -> 0.7 | F5: =IFERROR(SUMIFS(Data!G$3:G$97,Data!$A$3:$A$97,$A5,Data!$B$3:$B$97,2024),"n/a") -> 3.24 | G5: =IFERROR(SUMIFS(Data!H$3:H$97,Data!$A$3:$A$97,$A5,Data!$B$3:$B$97,2023),"n/a") -> 19806.45 | H5: =IFERROR(SUMIFS(Data!I$3:I$97,Data!$A$3:$A$97,$A5,Data!$B$3:$B$97,2023),"n/a") -> 33084.97 | I5: =IFERROR(SUMIFS(Data!J$3:J$97,Data!$A$3:$A$97,$A5,Data!$B$3:$B$97,2023),"n/a") -> 3189.39 | J5: =IFERROR(SUMIFS(Data!K$3:K$97,Data!$A$3:$A$97,$A5,Data!$B$3:$B$97,2023),"n/a") -> 52.56
A6: Djibouti | B6: =IFERROR(SUMIFS(Data!C$3:C$97,Data!$A$3:$A$97,$A6,Data!$B$3:$B$97,2023),"n/a") -> 2.61 | C6: =IFERROR(SUMIFS(Data!D$3:D$97,Data!$A$3:$A$97,$A6,Data!$B$3:$B$97,2023),"n/a") -> 65.99 | D6: =IFERROR(SUMIFS(Data!E$3:E$97,Data!$A$3:$A$97,$A6,Data!$B$3:$B$97,2023),"n/a") -> 44.4 | E6: =IFERROR(SUMIFS(Data!F$3:F$97,Data!$A$3:$A$97,$A6,Data!$B$3:$B$97,2024),"n/a") -> 0.9 | F6: =IFERROR(SUMIFS(Data!G$3:G$97,Data!$A$3:$A$97,$A6,Data!$B$3:$B$97,2024),"n/a") -> 1.36 | G6: =IFERROR(SUMIFS(Data!H$3:H$97,Data!$A$3:$A$97,$A6,Data!$B$3:$B$97,2023),"n/a") -> 226.7 | H6: =IFERROR(SUMIFS(Data!I$3:I$97,Data!$A$3:$A$97,$A6,Data!$B$3:$B$97,2023),"n/a") -> 523.63 | I6: =IFERROR(SUMIFS(Data!J$3:J$97,Data!$A$3:$A$97,$A6,Data!$B$3:$B$97,2023),"n/a") -> 53.57 | J6: =IFERROR(SUMIFS(Data!K$3:K$97,Data!$A$3:$A$97,$A6,Data!$B$3:$B$97,2023),"n/a") -> 21.45
A7: Eritrea | B7: =IFERROR(SUMIFS(Data!C$3:C$97,Data!$A$3:$A$97,$A7,Data!$B$3:$B$97,2023),"n/a") -> 3.71 | C7: =IFERROR(SUMIFS(Data!D$3:D$97,Data!$A$3:$A$97,$A7,Data!$B$3:$B$97,2023),"n/a") -> 68.62 | D7: =IFERROR(SUMIFS(Data!E$3:E$97,Data!$A$3:$A$97,$A7,Data!$B$3:$B$97,2023),"n/a") -> 25.5 | E7: =IFERROR(SUMIFS(Data!F$3:F$97,Data!$A$3:$A$97,$A7,Data!$B$3:$B$97,2024),"n/a") -> 0.4 | F7: =IFERROR(SUMIFS(Data!G$3:G$97,Data!$A$3:$A$97,$A7,Data!$B$3:$B$97,2024),"n/a") -> 1.86 | G7: =IFERROR(SUMIFS(Data!H$3:H$97,Data!$A$3:$A$97,$A7,Data!$B$3:$B$97,2023),"n/a") -> 760.38 | H7: =IFERROR(SUMIFS(Data!I$3:I$97,Data!$A$3:$A$97,$A7,Data!$B$3:$B$97,2023),"n/a") -> 1197.6 | I7: =IFERROR(SUMIFS(Data!J$3:J$97,Data!$A$3:$A$97,$A7,Data!$B$3:$B$97,2023),"n/a") -> 141.93 | J7: =IFERROR(SUMIFS(Data!K$3:K$97,Data!$A$3:$A$97,$A7,Data!$B$3:$B$97,2023),"n/a") -> 56.73
A8: Ethiopia | B8: =IFERROR(SUMIFS(Data!C$3:C$97,Data!$A$3:$A$97,$A8,Data!$B$3:$B$97,2023),"n/a") -> 3.99 | C8: =IFERROR(SUMIFS(Data!D$3:D$97,Data!$A$3:$A$97,$A8,Data!$B$3:$B$97,2023),"n/a") -> 67.31 | D8: =IFERROR(SUMIFS(Data!E$3:E$97,Data!$A$3:$A$97,$A8,Data!$B$3:$B$97,2023),"n/a") -> 35.7 | E8: =IFERROR(SUMIFS(Data!F$3:F$97,Data!$A$3:$A$97,$A8,Data!$B$3:$B$97,2024),"n/a") -> 0.7 | F8: =IFERROR(SUMIFS(Data!G$3:G$97,Data!$A$3:$A$97,$A8,Data!$B$3:$B$97,2024),"n/a") -> 2.58 | G8: =IFERROR(SUMIFS(Data!H$3:H$97,Data!$A$3:$A$97,$A8,Data!$B$3:$B$97,2023),"n/a") -> 26961.07 | H8: =IFERROR(SUMIFS(Data!I$3:I$97,Data!$A$3:$A$97,$A8,Data!$B$3:$B$97,2023),"n/a") -> 45858.2 | I8: =IFERROR(SUMIFS(Data!J$3:J$97,Data!$A$3:$A$97,$A8,Data!$B$3:$B$97,2023),"n/a") -> 3994.02 | J8: =IFERROR(SUMIFS(Data!K$3:K$97,Data!$A$3:$A$97,$A8,Data!$B$3:$B$97,2023),"n/a") -> 76.84
A9: Kenya | B9: =IFERROR(SUMIFS(Data!C$3:C$97,Data!$A$3:$A$97,$A9,Data!$B$3:$B$97,2023),"n/a") -> 3.21 | C9: =IFERROR(SUMIFS(Data!D$3:D$97,Data!$A$3:$A$97,$A9,Data!$B$3:$B$97,2023),"n/a") -> 63.65 | D9: =IFERROR(SUMIFS(Data!E$3:E$97,Data!$A$3:$A$97,$A9,Data!$B$3:$B$97,2023),"n/a") -> 34.7 | E9: =IFERROR(SUMIFS(Data!F$3:F$97,Data!$A$3:$A$97,$A9,Data!$B$3:$B$97,2024),"n/a") -> 3 | F9: =IFERROR(SUMIFS(Data!G$3:G$97,Data!$A$3:$A$97,$A9,Data!$B$3:$B$97,2024),"n/a") -> 1.96 | G9: =IFERROR(SUMIFS(Data!H$3:H$97,Data!$A$3:$A$97,$A9,Data!$B$3:$B$97,2023),"n/a") -> 11568.02 | H9: =IFERROR(SUMIFS(Data!I$3:I$97,Data!$A$3:$A$97,$A9,Data!$B$3:$B$97,2023),"n/a") -> 20952.31 | I9: =IFERROR(SUMIFS(Data!J$3:J$97,Data!$A$3:$A$97,$A9,Data!$B$3:$B$97,2023),"n/a") -> 1581.23 | J9: =IFERROR(SUMIFS(Data!K$3:K$97,Data!$A$3:$A$97,$A9,Data!$B$3:$B$97,2023),"n/a") -> 70.48
A10: Madagascar | B10: =IFERROR(SUMIFS(Data!C$3:C$97,Data!$A$3:$A$97,$A10,Data!$B$3:$B$97,2023),"n/a") -> 3.97 | C10: =IFERROR(SUMIFS(Data!D$3:D$97,Data!$A$3:$A$97,$A10,Data!$B$3:$B$97,2023),"n/a") -> 63.63 | D10: =IFERROR(SUMIFS(Data!E$3:E$97,Data!$A$3:$A$97,$A10,Data!$B$3:$B$97,2023),"n/a") -> 44.2 | E10: =IFERROR(SUMIFS(Data!F$3:F$97,Data!$A$3:$A$97,$A10,Data!$B$3:$B$97,2024),"n/a") -> 0.5 | F10: =IFERROR(SUMIFS(Data!G$3:G$97,Data!$A$3:$A$97,$A10,Data!$B$3:$B$97,2024),"n/a") -> 2.44 | G10: =IFERROR(SUMIFS(Data!H$3:H$97,Data!$A$3:$A$97,$A10,Data!$B$3:$B$97,2023),"n/a") -> 6270.33 | H10: =IFERROR(SUMIFS(Data!I$3:I$97,Data!$A$3:$A$97,$A10,Data!$B$3:$B$97,2023),"n/a") -> 11285.24 | I10: =IFERROR(SUMIFS(Data!J$3:J$97,Data!$A$3:$A$97,$A10,Data!$B$3:$B$97,2023),"n/a") -> 1016.6 | J10: =IFERROR(SUMIFS(Data!K$3:K$97,Data!$A$3:$A$97,$A10,Data!$B$3:$B$97,2023),"n/a") -> 59.44
A11: Malawi | B11: =IFERROR(SUMIFS(Data!C$3:C$97,Data!$A$3:$A$97,$A11,Data!$B$3:$B$97,2023),"n/a") -> 3.65 | C11: =IFERROR(SUMIFS(Data!D$3:D$97,Data!$A$3:$A$97,$A11,Data!$B$3:$B$97,2023),"n/a") -> 67.35 | D11: =IFERROR(SUMIFS(Data!E$3:E$97,Data!$A$3:$A$97,$A11,Data!$B$3:$B$97,2023),"n/a") -> 29.4 | E11: =IFERROR(SUMIFS(Data!F$3:F$97,Data!$A$3:$A$97,$A11,Data!$B$3:$B$97,2024),"n/a") -> 6.2 | F11: =IFERROR(SUMIFS(Data!G$3:G$97,Data!$A$3:$A$97,$A11,Data!$B$3:$B$97,2024),"n/a") -> 2.58 | G11: =IFERROR(SUMIFS(Data!H$3:H$97,Data!$A$3:$A$97,$A11,Data!$B$3:$B$97,2023),"n/a") -> 4462.43 | H11: =IFERROR(SUMIFS(Data!I$3:I$97,Data!$A$3:$A$97,$A11,Data!$B$3:$B$97,2023),"n/a") -> 7156.29 | I11: =IFERROR(SUMIFS(Data!J$3:J$97,Data!$A$3:$A$97,$A11,Data!$B$3:$B$97,2023),"n/a") -> 541.28 | J11: =IFERROR(SUMIFS(Data!K$3:K$97,Data!$A$3:$A$97,$A11,Data!$B$3:$B$97,2023),"n/a") -> 81.72
A12: Mauritius | B12: =IFERROR(SUMIFS(Data!C$3:C$97,Data!$A$3:$A$97,$A12,Data!$B$3:$B$97,2023),"n/a") -> 1.39 | C12: =IFERROR(SUMIFS(Data!D$3:D$97,Data!$A$3:$A$97,$A12,Data!$B$3:$B$97,2023),"n/a") -> 73.41 | D12: =IFERROR(SUMIFS(Data!E$3:E$97,Data!$A$3:$A$97,$A12,Data!$B$3:$B$97,2023),"n/a") -> 13.5 | E12: n/a | F12: =IFERROR(SUMIFS(Data!G$3:G$97,Data!$A$3:$A$97,$A12,Data!$B$3:$B$97,2024),"n/a") -> -0.12 | G12: =IFERROR(SUMIFS(Data!H$3:H$97,Data!$A$3:$A$97,$A12,Data!$B$3:$B$97,2023),"n/a") -> 185.4 | H12: =IFERROR(SUMIFS(Data!I$3:I$97,Data!$A$3:$A$97,$A12,Data!$B$3:$B$97,2023),"n/a") -> 733.16 | I12: =IFERROR(SUMIFS(Data!J$3:J$97,Data!$A$3:$A$97,$A12,Data!$B$3:$B$97,2023),"n/a") -> 161.22 | J12: =IFERROR(SUMIFS(Data!K$3:K$97,Data!$A$3:$A$97,$A12,Data!$B$3:$B$97,2023),"n/a") -> 59.13
A13: Mozambique | B13: =IFERROR(SUMIFS(Data!C$3:C$97,Data!$A$3:$A$97,$A13,Data!$B$3:$B$97,2023),"n/a") -> 4.76 | C13: =IFERROR(SUMIFS(Data!D$3:D$97,Data!$A$3:$A$97,$A13,Data!$B$3:$B$97,2023),"n/a") -> 63.61 | D13: =IFERROR(SUMIFS(Data!E$3:E$97,Data!$A$3:$A$97,$A13,Data!$B$3:$B$97,2023),"n/a") -> 45.4 | E13: =IFERROR(SUMIFS(Data!F$3:F$97,Data!$A$3:$A$97,$A13,Data!$B$3:$B$97,2024),"n/a") -> 11.5 | F13: =IFERROR(SUMIFS(Data!G$3:G$97,Data!$A$3:$A$97,$A13,Data!$B$3:$B$97,2024),"n/a") -> 2.92 | G13: =IFERROR(SUMIFS(Data!H$3:H$97,Data!$A$3:$A$97,$A13,Data!$B$3:$B$97,2023),"n/a") -> 6676.51 | H13: =IFERROR(SUMIFS(Data!I$3:I$97,Data!$A$3:$A$97,$A13,Data!$B$3:$B$97,2023),"n/a") -> 10673.34 | I13: =IFERROR(SUMIFS(Data!J$3:J$97,Data!$A$3:$A$97,$A13,Data!$B$3:$B$97,2023),"n/a") -> 918.4 | J13: =IFERROR(SUMIFS(Data!K$3:K$97,Data!$A$3:$A$97,$A13,Data!$B$3:$B$97,2023),"n/a") -> 61.25
A14: Rwanda | B14: =IFERROR(SUMIFS(Data!C$3:C$97,Data!$A$3:$A$97,$A14,Data!$B$3:$B$97,2023),"n/a") -> 3.7 | C14: =IFERROR(SUMIFS(Data!D$3:D$97,Data!$A$3:$A$97,$A14,Data!$B$3:$B$97,2023),"n/a") -> 67.78 | D14: =IFERROR(SUMIFS(Data!E$3:E$97,Data!$A$3:$A$97,$A14,Data!$B$3:$B$97,2023),"n/a") -> 30.5 | E14: =IFERROR(SUMIFS(Data!F$3:F$97,Data!$A$3:$A$97,$A14,Data!$B$3:$B$97,2024),"n/a") -> 2 | F14: =IFERROR(SUMIFS(Data!G$3:G$97,Data!$A$3:$A$97,$A14,Data!$B$3:$B$97,2024),"n/a") -> 2.14 | G14: =IFERROR(SUMIFS(Data!H$3:H$97,Data!$A$3:$A$97,$A14,Data!$B$3:$B$97,2023),"n/a") -> 2830.47 | H14: n/a | I14: =IFERROR(SUMIFS(Data!J$3:J$97,Data!$A$3:$A$97,$A14,Data!$B$3:$B$97,2023),"n/a") -> 520.18 | J14: =IFERROR(SUMIFS(Data!K$3:K$97,Data!$A$3:$A$97,$A14,Data!$B$3:$B$97,2023),"n/a") -> 82.11
A15: Seychelles | B15: =IFERROR(SUMIFS(Data!C$3:C$97,Data!$A$3:$A$97,$A15,Data!$B$3:$B$97,2023),"n/a") -> 2.02 | C15: =IFERROR(SUMIFS(Data!D$3:D$97,Data!$A$3:$A$97,$A15,Data!$B$3:$B$97,2023),"n/a") -> 74.96 | D15: =IFERROR(SUMIFS(Data!E$3:E$97,Data!$A$3:$A$97,$A15,Data!$B$3:$B$97,2023),"n/a") -> 13.1 | E15: n/a | F15: =IFERROR(SUMIFS(Data!G$3:G$97,Data!$A$3:$A$97,$A15,Data!$B$3:$B$97,2024),"n/a") -> 1.31 | G15: =IFERROR(SUMIFS(Data!H$3:H$97,Data!$A$3:$A$97,$A15,Data!$B$3:$B$97,2023),"n/a") -> 16.19 | H15: n/a | I15: =IFERROR(SUMIFS(Data!J$3:J$97,Data!$A$3:$A$97,$A15,Data!$B$3:$B$97,2023),"n/a") -> 10.41 | J15: =IFERROR(SUMIFS(Data!K$3:K$97,Data!$A$3:$A$97,$A15,Data!$B$3:$B$97,2023),"n/a") -> 41.18
A16: Somalia | B16: =IFERROR(SUMIFS(Data!C$3:C$97,Data!$A$3:$A$97,$A16,Data!$B$3:$B$97,2023),"n/a") -> 6.13 | C16: =IFERROR(SUMIFS(Data!D$3:D$97,Data!$A$3:$A$97,$A16,Data!$B$3:$B$97,2023),"n/a") -> 58.82 | D16: =IFERROR(SUMIFS(Data!E$3:E$97,Data!$A$3:$A$97,$A16,Data!$B$3:$B$97,2023),"n/a") -> 67.8 | E16: =IFERROR(SUMIFS(Data!F$3:F$97,Data!$A$3:$A$97,$A16,Data!$B$3:$B$97,2024),"n/a") -> 0.1 | F16: =IFERROR(SUMIFS(Data!G$3:G$97,Data!$A$3:$A$97,$A16,Data!$B$3:$B$97,2024),"n/a") -> 3.48 | G16: =IFERROR(SUMIFS(Data!H$3:H$97,Data!$A$3:$A$97,$A16,Data!$B$3:$B$97,2023),"n/a") -> 3628.7 | H16: n/a | I16: =IFERROR(SUMIFS(Data!J$3:J$97,Data!$A$3:$A$97,$A16,Data!$B$3:$B$97,2023),"n/a") -> 459.98 | J16: =IFERROR(SUMIFS(Data!K$3:K$97,Data!$A$3:$A$97,$A16,Data!$B$3:$B$97,2023),"n/a") -> 52.08
A17: South Sudan | B17: =IFERROR(SUMIFS(Data!C$3:C$97,Data!$A$3:$A$97,$A17,Data!$B$3:$B$97,2023),"n/a") -> 3.86 | C17: =IFERROR(SUMIFS(Data!D$3:D$97,Data!$A$3:$A$97,$A17,Data!$B$3:$B$97,2023),"n/a") -> 57.62 | D17: =IFERROR(SUMIFS(Data!E$3:E$97,Data!$A$3:$A$97,$A17,Data!$B$3:$B$97,2023),"n/a") -> 72.6 | E17: =IFERROR(SUMIFS(Data!F$3:F$97,Data!$A$3:$A$97,$A17,Data!$B$3:$B$97,2024),"n/a") -> 1.5 | F17: =IFERROR(SUMIFS(Data!G$3:G$97,Data!$A$3:$A$97,$A17,Data!$B$3:$B$97,2024),"n/a") -> 3.93 | G17: =IFERROR(SUMIFS(Data!H$3:H$97,Data!$A$3:$A$97,$A17,Data!$B$3:$B$97,2023),"n/a") -> 2443.3 | H17: n/a | I17: =IFERROR(SUMIFS(Data!J$3:J$97,Data!$A$3:$A$97,$A17,Data!$B$3:$B$97,2023),"n/a") -> 320.22 | J17: =IFERROR(SUMIFS(Data!K$3:K$97,Data!$A$3:$A$97,$A17,Data!$B$3:$B$97,2023),"n/a") -> 78.81
A18: Uganda | B18: =IFERROR(SUMIFS(Data!C$3:C$97,Data!$A$3:$A$97,$A18,Data!$B$3:$B$97,2023),"n/a") -> 4.28 | C18: =IFERROR(SUMIFS(Data!D$3:D$97,Data!$A$3:$A$97,$A18,Data!$B$3:$B$97,2023),"n/a") -> 68.25 | D18: =IFERROR(SUMIFS(Data!E$3:E$97,Data!$A$3:$A$97,$A18,Data!$B$3:$B$97,2023),"n/a") -> 27.6 | E18: =IFERROR(SUMIFS(Data!F$3:F$97,Data!$A$3:$A$97,$A18,Data!$B$3:$B$97,2024),"n/a") -> 4.9 | F18: =IFERROR(SUMIFS(Data!G$3:G$97,Data!$A$3:$A$97,$A18,Data!$B$3:$B$97,2024),"n/a") -> 2.75 | G18: =IFERROR(SUMIFS(Data!H$3:H$97,Data!$A$3:$A$97,$A18,Data!$B$3:$B$97,2023),"n/a") -> 10472.6 | H18: n/a | I18: =IFERROR(SUMIFS(Data!J$3:J$97,Data!$A$3:$A$97,$A18,Data!$B$3:$B$97,2023),"n/a") -> 1022.87 | J18: =IFERROR(SUMIFS(Data!K$3:K$97,Data!$A$3:$A$97,$A18,Data!$B$3:$B$97,2023),"n/a") -> 73.23
A19: United Republic of Tanzania | B19: =IFERROR(SUMIFS(Data!C$3:C$97,Data!$A$3:$A$97,$A19,Data!$B$3:$B$97,2023),"n/a") -> 4.61 | C19: =IFERROR(SUMIFS(Data!D$3:D$97,Data!$A$3:$A$97,$A19,Data!$B$3:$B$97,2023),"n/a") -> 67 | D19: =IFERROR(SUMIFS(Data!E$3:E$97,Data!$A$3:$A$97,$A19,Data!$B$3:$B$97,2023),"n/a") -> 29.9 | E19: =IFERROR(SUMIFS(Data!F$3:F$97,Data!$A$3:$A$97,$A19,Data!$B$3:$B$97,2024),"n/a") -> 3.5 | F19: =IFERROR(SUMIFS(Data!G$3:G$97,Data!$A$3:$A$97,$A19,Data!$B$3:$B$97,2024),"n/a") -> 2.87 | G19: =IFERROR(SUMIFS(Data!H$3:H$97,Data!$A$3:$A$97,$A19,Data!$B$3:$B$97,2023),"n/a") -> 13302.56 | H19: n/a | I19: =IFERROR(SUMIFS(Data!J$3:J$97,Data!$A$3:$A$97,$A19,Data!$B$3:$B$97,2023),"n/a") -> 1996.28 | J19: =IFERROR(SUMIFS(Data!K$3:K$97,Data!$A$3:$A$97,$A19,Data!$B$3:$B$97,2023),"n/a") -> 62.59
A20: Zambia | B20: =IFERROR(SUMIFS(Data!C$3:C$97,Data!$A$3:$A$97,$A20,Data!$B$3:$B$97,2023),"n/a") -> 4.1 | C20: =IFERROR(SUMIFS(Data!D$3:D$97,Data!$A$3:$A$97,$A20,Data!$B$3:$B$97,2023),"n/a") -> 66.35 | D20: =IFERROR(SUMIFS(Data!E$3:E$97,Data!$A$3:$A$97,$A20,Data!$B$3:$B$97,2023),"n/a") -> 30.9 | E20: =IFERROR(SUMIFS(Data!F$3:F$97,Data!$A$3:$A$97,$A20,Data!$B$3:$B$97,2024),"n/a") -> 9.4 | F20: =IFERROR(SUMIFS(Data!G$3:G$97,Data!$A$3:$A$97,$A20,Data!$B$3:$B$97,2024),"n/a") -> 2.81 | G20: =IFERROR(SUMIFS(Data!H$3:H$97,Data!$A$3:$A$97,$A20,Data!$B$3:$B$97,2023),"n/a") -> 4198.53 | H20: n/a | I20: =IFERROR(SUMIFS(Data!J$3:J$97,Data!$A$3:$A$97,$A20,Data!$B$3:$B$97,2023),"n/a") -> 383.31 | J20: =IFERROR(SUMIFS(Data!K$3:K$97,Data!$A$3:$A$97,$A20,Data!$B$3:$B$97,2023),"n/a") -> 53.66
A21: Zimbabwe | B21: =IFERROR(SUMIFS(Data!C$3:C$97,Data!$A$3:$A$97,$A21,Data!$B$3:$B$97,2023),"n/a") -> 3.72 | C21: =IFERROR(SUMIFS(Data!D$3:D$97,Data!$A$3:$A$97,$A21,Data!$B$3:$B$97,2023),"n/a") -> 62.77 | D21: =IFERROR(SUMIFS(Data!E$3:E$97,Data!$A$3:$A$97,$A21,Data!$B$3:$B$97,2023),"n/a") -> 40.6 | E21: =IFERROR(SUMIFS(Data!F$3:F$97,Data!$A$3:$A$97,$A21,Data!$B$3:$B$97,2024),"n/a") -> 9.8 | F21: =IFERROR(SUMIFS(Data!G$3:G$97,Data!$A$3:$A$97,$A21,Data!$B$3:$B$97,2024),"n/a") -> 1.78 | G21: =IFERROR(SUMIFS(Data!H$3:H$97,Data!$A$3:$A$97,$A21,Data!$B$3:$B$97,2023),"n/a") -> 3336.47 | H21: n/a | I21: =IFERROR(SUMIFS(Data!J$3:J$97,Data!$A$3:$A$97,$A21,Data!$B$3:$B$97,2023),"n/a") -> 586.22 | J21: =IFERROR(SUMIFS(Data!K$3:K$97,Data!$A$3:$A$97,$A21,Data!$B$3:$B$97,2023),"n/a") -> 67.48
